Workbook

Sheet Cover
B2: Change Log
B3: Merchant Payment Operations & Dispute Hub
B5: Document | C5: Change Request (CR) Log
B6: Version | C6: 1.0
B7: Reporting date | C7: 46275
B8: Prepared by | C8: Bhawna, Product Owner
B9: Review cadence | C9: Weekly change review with the RAID log; High-impact changes to steering committee
B10: Companion document | C10: RAID_Log_Merchant_Dispute_Hub.xlsx (Linked Items column references R-, A-, I-, D- IDs)
B11: Project type | C11: Simulation / portfolio project prepared to demonstrate Product Owner practice. Not an actual client system; teams, dates, costs and vendors are illustrative.
B13: Purpose
B14: This log records every proposed change to an agreed project baseline (scope, schedule, effort, cost, requirements, design or compliance commitments), the impact assessment, the options considered, who decided and why, and whether the plan was updated. The Dashboard tab shows pending decisions and the cumulative impact of approved changes against contingency.
B16: What goes in this log
B17: Log as a change request | E17: Handle in backlog refinement (no CR needed)
B18: Adds, removes or changes agreed MVP scope | E18: Reprioritizing stories within the sprint goal
B19: Moves go-live or a committed milestone | E19: Splitting or re-estimating stories
B20: Uses effort or budget beyond agreed contingency | E20: Swapping stories of similar size with no release impact
B21: Changes a compliance, security or contractual commitment | E21: Clarifying acceptance criteria without changing intent
B22: Changes an approved requirement or design other teams depend on | E22: Fixing defects against existing requirements
B24: Impact rating and decision authority
B25: Impact rating is calculated from the assessed impact of the change as requested. A change is rated at the highest level any threshold reaches. Compliance changes are always rated High. Edit the yellow cells to change thresholds; the log recalculates.
B26: Rating | C26: Schedule (working days) ≥ | D26: Effort (story points) ≥ | E26: Cost (USD) ≥ | F26: Required approver
B27: High | C27: 5 | D27: 40 | E27: 50000 | F27: Steering Committee
B28: Medium | C28: 2 | D28: 13 | E28: 10000 | F28: Business Sponsor
B29: Low | C29: Below Medium | D29: Below Medium | E29: Below Medium | F29: Product Owner
B30: Unassessed changes show 'To assess' and route to the Product Owner for triage.
B32: Stage and decision values
B33: Field | C33: Values
B34: Stage | C34: Logged → Under Assessment → Awaiting Decision → Implementing → Closed. Rejected, deferred and withdrawn CRs move straight to Closed.
B35: Decision | C35: Pending · Approved · Approved with Conditions · Rejected · Deferred (moved to a later phase) · Withdrawn (requester no longer needs it)
B36: Implementation | C36: Not Started · In Progress · Implemented · Verified · N/A
B38: How to maintain this log
B39: 1. Log every request, including ones likely to be rejected. IDs follow CR-##.
B40: 2. Triage within 2 business days: is this a baseline change or normal backlog refinement?
B41: 3. Complete the impact assessment with the Tech Lead, BA and Compliance within 5 business days. Always offer options, not only yes or no.
B42: 4. Take the change to the required approver before the Decision Needed By date. Record who decided, when and why; no verbal-only approvals.
B43: 5. Record the approved impact (which may be smaller than requested), then update the backlog, release plan, RAID log and SOW as needed and list them in Baselines Updated.
B44: 6. Close the CR once implemented and verified. Never delete rows; rejected and deferred changes are part of the audit trail.
B45: Grey columns in the log calculate automatically. Yellow cells on the Cover and Dashboard are editable settings.
B47: Version history
B48: Version | C48: Date | D48: Author | E48: Change summary
...

Sheet Dashboard
B1: Change Control Dashboard
B2: Merchant Payment Operations & Dispute Hub · Simulation project · Figures update automatically from the Change Log
B3: ="Reporting date: "&TEXT(Cover!$C$7,"DD-MMM-YYYY") -> Reporting date: 10-Sep-2026
B5: Summary
B6: Total CRs | C6: Pending decision | D6: Approved (incl. conditions) | E6: Rejected | F6: Deferred / Withdrawn | G6: Approval rate | H6: Avg days to decision | I6: Decisions overdue
B7: =COUNTA('Change Log'!$A$5:$A$54) -> 9 | C7: =COUNTIFS('Change Log'!$U$5:$U$54,"Pending") -> 4 | D7: =COUNTIFS('Change Log'!$U$5:$U$54,"Approved")+COUNTIFS('Change Log'!$U$5:$U$54,"Approved with Conditions") -> 3 | E7: =COUNTIFS('Change Log'!$U$5:$U$54,"Rejected") -> 1 | F7: =COUNTIFS('Change Log'!$U$5:$U$54,"Deferred")+COUNTIFS('Change Log'!$U$5:$U$54,"Withdrawn") -> 1 | G7: =IFERROR(D7/(D7+E7+F7),0) -> 0.6 | H7: =IFERROR(AVERAGEIFS('Change Log'!$AE$5:$AE$54,'Change Log'!$U$5:$U$54,"<>Pending",'Change Log'!$A$5:$A$54,"<>"),"") -> 8 | I7: =COUNTIFS('Change Log'!$AF$5:$AF$54,"Overdue") -> 0
B9: Cumulative impact against contingency
B10: Measure | D10: Contingency agreed at baseline | E10: Approved changes to date | F10: Contingency remaining | G10: Pending CRs (as requested) | H10: Remaining if all pending approved as requested
B11: Schedule (working days) | D11: 10 | E11: =SUMIFS('Change Log'!$Y$5:$Y$54,'Change Log'!$U$5:$U$54,"Approved")+SUMIFS('Change Log'!$Y$5:$Y$54,'Change Log'!$U$5:$U$54,"Approved with Conditions") -> 9 | F11: =D11-E11 -> 1 | G11: =SUMIFS('Change Log'!$K$5:$K$54,'Change Log'!$U$5:$U$54,"Pending") -> 18 | H11: =F11-G11 -> -17
B12: Effort (story points) | D12: 80 | E12: =SUMIFS('Change Log'!$Z$5:$Z$54,'Change Log'!$U$5:$U$54,"Approved")+SUMIFS('Change Log'!$Z$5:$Z$54,'Change Log'!$U$5:$U$54,"Approved with Conditions") -> 37 | F12: =D12-E12 -> 43 | G12: =SUMIFS('Change Log'!$L$5:$L$54,'Change Log'!$U$5:$U$54,"Pending") -> 68 | H12: =F12-G12 -> -25
B13: Cost (USD) | D13: 75000 | E13: =SUMIFS('Change Log'!$AA$5:$AA$54,'Change Log'!$U$5:$U$54,"Approved")+SUMIFS('Change Log'!$AA$5:$AA$54,'Change Log'!$U$5:$U$54,"Approved with Conditions") -> 28500 | F13: =D13-E13 -> 46500 | G13: =SUMIFS('Change Log'!$M$5:$M$54,'Change Log'!$U$5:$U$54,"Pending") -> 76000 | H13: =F13-G13 -> -29500
B14: Yellow cells are illustrative baseline settings; edit them to match the agreed plan. Pending figures use impact as requested, before any smaller option is chosen.
B16: Go-live forecast
B17: Measure | D17: Date | E17: How it's calculated
B18: Baseline go-live (includes schedule contingency) | D18: 46367 | E18: Agreed at MVP scope baseline
B19: Forecast go-live with approved changes | D19: =WORKDAY(D18,MAX(0,E11-D11)) -> 46367 | E19: Moves only if approved schedule impact exceeds contingency
B20: Forecast if all pending CRs approved as requested | D20: =WORKDAY(D18,MAX(0,E11+G11-D11)) -> 46392 | E20: Worst case; shows why options matter for pending decisions
B22: Decisions needed (pending CRs, earliest deadline first)
B23: CR ID | C23: Title | D23: Impact rating | E23: Required approver | F23: Decision needed by | G23: Recommendation | I23: Overdue?
B24: =IFERROR(IF(INDEX('Change Log'!$A$5:$A$54,MATCH(SMALL('Change Log'!$AH$5:$AH$54,1),'Change Log'!$AH$5:$AH$54,0))="","",INDEX('Change Log'!$A$5:$A$54,MATCH(SMALL('Change Log'!$AH$5:$AH$54,1),'Change Log'!$AH$5:$AH$54,0))),"") -> CR-05 | C24: =IFERROR(IF(INDEX('Change Log'!$B$5:$B$54,MATCH(SMALL('Change Log'!$AH$5:$AH$54,1),'Change Log'!$AH$5:$AH$54,0))="","",INDEX('Change Log'!$B$5:$B$54,MATCH(SMALL('Change Log'!$AH$5:$AH$54,1),'Change Log'!$AH$5:$AH$54,0))),"") -> Change how dispute outcomes are reported | D24: =IFERROR(IF(INDEX('Change Log'!$N$5:$N$54,MATCH(SMALL('Change Log'!$AH$5:$AH$54,1),'Change Log'!$AH$5:$AH$54,0))="","",INDEX('Change Log'!$N$5:$N$54,MATCH(SMALL('Change Log'!$AH$5:$AH$54,1),'Change Log'!$AH$5:$AH$54,0))),"") -> Medium | E24: =IFERROR(IF(INDEX('Change Log'!$O$5:$O$54,MATCH(SMALL('Change Log'!$AH$5:$AH$54,1),'Change Log'!$AH$5:$AH$54,0))="","",INDEX('Change Log'!$O$5:$O$54,MATCH(SMALL('Change Log'!$AH$5:$AH$54,1),'Change Log'!$AH$5:$AH$54,0))),"") -> Business Sponsor | F24: =IFERROR(IF(INDEX('Change Log'!$S$5:$S$54,MATCH(SMALL('Change Log'!$AH$5:$AH$54,1),'Change Log'!$AH$5:$AH$54,0))="","",INDEX('Change Log'!$S$5:$S$54,MATCH(SMALL('Change Log'!$AH$5:$AH$54,1),'Change Log'!$AH$5:$AH$54,0))),"") -> 46283 | G24: =IFERROR(IF(INDEX('Change Log'!$Q$5:$Q$54,MATCH(SMALL('Change Log'!$AH$5:$AH$54,1),'Change Log'!$AH$5:$AH$54,0))="","",INDEX('Change Log'!$Q$5:$Q$54,MATCH(SMALL('Change Log'!$AH$5:$AH$54,1),'Change Log'!$AH$5:$AH$54,0))),"") -> Option C. Keeps both teams' views visible and avoids re-defining the KPI later. | I24: =IFERROR(IF(INDEX('Change Log'!$AF$5:$AF$54,MATCH(SMALL('Change Log'!$AH$5:$AH$54,1),'Change Log'!$AH$5:$AH$54,0))="","",INDEX('Change Log'!$AF$5:$AF$54,MATCH(SMALL('Change Log'!$AH$5:$AH$54,1),'Change Log'!$AH$5:$AH$54,0))),"") -> No
B25: =IFERROR(IF(INDEX('Change Log'!$A$5:$A$54,MATCH(SMALL('Change Log'!$AH$5:$AH$54,2),'Change Log'!$AH$5:$AH$54,0))="","",INDEX('Change Log'!$A$5:$A$54,MATCH(SMALL('Change Log'!$AH$5:$AH$54,2),'Change Log'!$AH$5:$AH$54,0))),"") -> CR-01 | C25: =IFERROR(IF(INDEX('Change Log'!$B$5:$B$54,MATCH(SMALL('Change Log'!$AH$5:$AH$54,2),'Change Log'!$AH$5:$AH$54,0))="","",INDEX('Change Log'!$B$5:$B$54,MATCH(SMALL('Change Log'!$AH$5:$AH$54,2),'Change Log'!$AH$5:$AH$54,0))),"") -> Add fraud case management to Dispute Hub MVP | D25: =IFERROR(IF(INDEX('Change Log'!$N$5:$N$54,MATCH(SMALL('Change Log'!$AH$5:$AH$54,2),'Change Log'!$AH$5:$AH$54,0))="","",INDEX('Change Log'!$N$5:$N$54,MATCH(SMALL('Change Log'!$AH$5:$AH$54,2),'Change Log'!$AH$5:$AH$54,0))),"") -> High | E25: =IFERROR(IF(INDEX('Change Log'!$O$5:$O$54,MATCH(SMALL('Change Log'!$AH$5:$AH$54,2),'Change Log'!$AH$5:$AH$54,0))="","",INDEX('Change Log'!$O$5:$O$54,MATCH(SMALL('Change Log'!$AH$5:$AH$54,2),'Change Log'!$AH$5:$AH$54,0))),"") -> Steering Committee | F25: =IFERROR(IF(INDEX('Change Log'!$S$5:$S$54,MATCH(SMALL('Change Log'!$AH$5:$AH$54,2),'Change Log'!$AH$5:$AH$54,0))="","",INDEX('Change Log'!$S$5:$S$54,MATCH(SMALL('Change Log'!$AH$5:$AH$54,2),'Change Log'!$AH$5:$AH$54,0))),"") -> 46290 | G25: =IFERROR(IF(INDEX('Change Log'!$Q$5:$Q$54,MATCH(SMALL('Change Log'!$AH$5:$AH$54,2),'Change Log'!$AH$5:$AH$54,0))="","",INDEX('Change Log'!$Q$5:$Q$54,MATCH(SMALL('Change Log'!$AH$5:$AH$54,2),'Change Log'!$AH$5:$AH$54,0))),"") -> Option C. Meets the core need (agents can see a linked case) without moving go-live. | I25: =IFERROR(IF(INDEX('Change Log'!$AF$5:$AF$54,MATCH(SMALL('Change Log'!$AH$5:$AH$54,2),'Change Log'!$AH$5:$AH$54,0))="","",INDEX('Change Log'!$AF$5:$AF$54,MATCH(SMALL('Change Log'!$AH$5:$AH$54,2),'Change Log'!$AH$5:$AH$54,0))),"") -> No
B26: =IFERROR(IF(INDEX('Change Log'!$A$5:$A$54,MATCH(SMALL('Change Log'!$AH$5:$AH$54,3),'Change Log'!$AH$5:$AH$54,0))="","",INDEX('Change Log'!$A$5:$A$54,MATCH(SMALL('Change Log'!$AH$5:$AH$54,3),'Change Log'!$AH$5:$AH$54,0))),"") -> CR-06 | C26: =IFERROR(IF(INDEX('Change Log'!$B$5:$B$54,MATCH(SMALL('Change Log'!$AH$5:$AH$54,3),'Change Log'!$AH$5:$AH$54,0))="","",INDEX('Change Log'!$B$5:$B$54,MATCH(SMALL('Change Log'!$AH$5:$AH$54,3),'Change Log'!$AH$5:$AH$54,0))),"") -> Run UAT in parallel with delayed penetration test | D26: =IFERROR(IF(INDEX('Change Log'!$N$5:$N$54,MATCH(SMALL('Change Log'!$AH$5:$AH$54,3),'Change Log'!$AH$5:$AH$54,0))="","",INDEX('Change Log'!$N$5:$N$54,MATCH(SMALL('Change Log'!$AH$5:$AH$54,3),'Change Log'!$AH$5:$AH$54,0))),"") -> High | E26: =IFERROR(IF(INDEX('Change Log'!$O$5:$O$54,MATCH(SMALL('Change Log'!$AH$5:$AH$54,3),'Change Log'!$AH$5:$AH$54,0))="","",INDEX('Change Log'!$O$5:$O$54,MATCH(SMALL('Change Log'!$AH$5:$AH$54,3),'Change Log'!$AH$5:$AH$54,0))),"") -> Steering Committee | F26: =IFERROR(IF(INDEX('Change Log'!$S$5:$S$54,MATCH(SMALL('Change Log'!$AH$5:$AH$54,3),'Change Log'!$AH$5:$AH$54,0))="","",INDEX('Change Log'!$S$5:$S$54,MATCH(SMALL('Change Log'!$AH$5:$AH$54,3),'Change Log'!$AH$5:$AH$54,0))),"") -> 46290 | G26: =IFERROR(IF(INDEX('Change Log'!$Q$5:$Q$54,MATCH(SMALL('Change Log'!$AH$5:$AH$54,3),'Change Log'!$AH$5:$AH$54,0))="","",INDEX('Change Log'!$Q$5:$Q$54,MATCH(SMALL('Change Log'!$AH$5:$AH$54,3),'Change Log'!$AH$5:$AH$54,0))),"") -> Option B, subject to Compliance agreeing security sign-off can follow UAT start. | I26: =IFERROR(IF(INDEX('Change Log'!$AF$5:$AF$54,MATCH(SMALL('Change Log'!$AH$5:$AH$54,3),'Change Log'!$AH$5:$AH$54,0))="","",INDEX('Change Log'!$AF$5:$AF$54,MATCH(SMALL('Change Log'!$AH$5:$AH$54,3),'Change Log'!$AH$5:$AH$54,0))),"") -> No
B27: =IFERROR(IF(INDEX('Change Log'!$A$5:$A$54,MATCH(SMALL('Change Log'!$AH$5:$AH$54,4),'Change Log'!$AH$5:$AH$54,0))="","",INDEX('Change Log'!$A$5:$A$54,MATCH(SMALL('Change Log'!$AH$5:$AH$54,4),'Change Log'!$AH$5:$AH$54,0))),"") -> CR-09 | C27: =IFERROR(IF(INDEX('Change Log'!$B$5:$B$54,MATCH(SMALL('Change Log'!$AH$5:$AH$54,4),'Change Log'!$AH$5:$AH$54,0))="","",INDEX('Change Log'!$B$5:$B$54,MATCH(SMALL('Change Log'!$AH$5:$AH$54,4),'Change Log'!$AH$5:$AH$54,0))),"") -> Add SMS reminders for dispute deadlines | D27: =IFERROR(IF(INDEX('Change Log'!$N$5:$N$54,MATCH(SMALL('Change Log'!$AH$5:$AH$54,4),'Change Log'!$AH$5:$AH$54,0))="","",INDEX('Change Log'!$N$5:$N$54,MATCH(SMALL('Change Log'!$AH$5:$AH$54,4),'Change Log'!$AH$5:$AH$54,0))),"") -> To assess | E27: =IFERROR(IF(INDEX('Change Log'!$O$5:$O$54,MATCH(SMALL('Change Log'!$AH$5:$AH$54,4),'Change Log'!$AH$5:$AH$54,0))="","",INDEX('Change Log'!$O$5:$O$54,MATCH(SMALL('Change Log'!$AH$5:$AH$54,4),'Change Log'!$AH$5:$AH$54,0))),"") -> Product Owner | F27: =IFERROR(IF(INDEX('Change Log'!$S$5:$S$54,MATCH(SMALL('Change Log'!$AH$5:$AH$54,4),'Change Log'!$AH$5:$AH$54,0))="","",INDEX('Change Log'!$S$5:$S$54,MATCH(SMALL('Change Log'!$AH$5:$AH$54,4),'Change Log'!$AH$5:$AH$54,0))),"") -> 46297 | G27: =IFERROR(IF(INDEX('Change Log'!$Q$5:$Q$54,MATCH(SMALL('Change Log'!$AH$5:$AH$54,4),'Change Log'!$AH$5:$AH$54,0))="","",INDEX('Change Log'!$Q$5:$Q$54,MATCH(SMALL('Change Log'!$AH$5:$AH$54,4),'Change Log'!$AH$5:$AH$54,0))),"") | I27: =IFERROR(IF(INDEX('Change Log'!$AF$5:$AF$54,MATCH(SMALL('Change Log'!$AH$5:$AH$54,4),'Change Log'!$AH$5:$AH$54,0))="","",INDEX('Change Log'!$AF$5:$AF$54,MATCH(SMALL('Change Log'!$AH$5:$AH$54,4),'Change Log'!$AH$5:$AH$54,0))),"") -> No
B28: =IFERROR(IF(INDEX('Change Log'!$A$5:$A$54,MATCH(SMALL('Change Log'!$AH$5:$AH$54,5),'Change Log'!$AH$5:$AH$54,0))="","",INDEX('Change Log'!$A$5:$A$54,MATCH(SMALL('Change Log'!$AH$5:$AH$54,5),'Change Log'!$AH$5:$AH$54,0))),"") | C28: =IFERROR(IF(INDEX('Change Log'!$B$5:$B$54,MATCH(SMALL('Change Log'!$AH$5:$AH$54,5),'Change Log'!$AH$5:$AH$54,0))="","",INDEX('Change Log'!$B$5:$B$54,MATCH(SMALL('Change Log'!$AH$5:$AH$54,5),'Change Log'!$AH$5:$AH$54,0))),"") | D28: =IFERROR(IF(INDEX('Change Log'!$N$5:$N$54,MATCH(SMALL('Change Log'!$AH$5:$AH$54,5),'Change Log'!$AH$5:$AH$54,0))="","",INDEX('Change Log'!$N$5:$N$54,MATCH(SMALL('Change Log'!$AH$5:$AH$54,5),'Change Log'!$AH$5:$AH$54,0))),"") | E28: =IFERROR(IF(INDEX('Change Log'!$O$5:$O$54,MATCH(SMALL('Change Log'!$AH$5:$AH$54,5),'Change Log'!$AH$5:$AH$54,0))="","",INDEX('Change Log'!$O$5:$O$54,MATCH(SMALL('Change Log'!$AH$5:$AH$54,5),'Change Log'!$AH$5:$AH$54,0))),"") | F28: =IFERROR(IF(INDEX('Change Log'!$S$5:$S$54,MATCH(SMALL('Change Log'!$AH$5:$AH$54,5),'Change Log'!$AH$5:$AH$54,0))="","",INDEX('Change Log'!$S$5:$S$54,MATCH(SMALL('Change Log'!$AH$5:$AH$54,5),'Change Log'!$AH$5:$AH$54,0))),"") | G28: =IFERROR(IF(INDEX('Change Log'!$Q$5:$Q$54,MATCH(SMALL('Change Log'!$AH$5:$AH$54,5),'Change Log'!$AH$5:$AH$54,0))="","",INDEX('Change Log'!$Q$5:$Q$54,MATCH(SMALL('Change Log'!$AH$5:$AH$54,5),'Change Log'!$AH$5:$AH$54,0))),"") | I28: =IFERROR(IF(INDEX('Change Log'!$AF$5:$AF$54,MATCH(SMALL('Change Log'!$AH$5:$AH$54,5),'Change Log'!$AH$5:$AH$54,0))="","",INDEX('Change Log'!$AF$5:$AF$54,MATCH(SMALL('Change Log'!$AH$5:$AH$54,5),'Change Log'!$AH$5:$AH$54,0))),"")
B29: =IFERROR(IF(INDEX('Change Log'!$A$5:$A$54,MATCH(SMALL('Change Log'!$AH$5:$AH$54,6),'Change Log'!$AH$5:$AH$54,0))="","",INDEX('Change Log'!$A$5:$A$54,MATCH(SMALL('Change Log'!$AH$5:$AH$54,6),'Change Log'!$AH$5:$AH$54,0))),"") | C29: =IFERROR(IF(INDEX('Change Log'!$B$5:$B$54,MATCH(SMALL('Change Log'!$AH$5:$AH$54,6),'Change Log'!$AH$5:$AH$54,0))="","",INDEX('Change Log'!$B$5:$B$54,MATCH(SMALL('Change Log'!$AH$5:$AH$54,6),'Change Log'!$AH$5:$AH$54,0))),"") | D29: =IFERROR(IF(INDEX('Change Log'!$N$5:$N$54,MATCH(SMALL('Change Log'!$AH$5:$AH$54,6),'Change Log'!$AH$5:$AH$54,0))="","",INDEX('Change Log'!$N$5:$N$54,MATCH(SMALL('Change Log'!$AH$5:$AH$54,6),'Change Log'!$AH$5:$AH$54,0))),"") | E29: =IFERROR(IF(INDEX('Change Log'!$O$5:$O$54,MATCH(SMALL('Change Log'!$AH$5:$AH$54,6),'Change Log'!$AH$5:$AH$54,0))="","",INDEX('Change Log'!$O$5:$O$54,MATCH(SMALL('Change Log'!$AH$5:$AH$54,6),'Change Log'!$AH$5:$AH$54,0))),"") | F29: =IFERROR(IF(INDEX('Change Log'!$S$5:$S$54,MATCH(SMALL('Change Log'!$AH$5:$AH$54,6),'Change Log'!$AH$5:$AH$54,0))="","",INDEX('Change Log'!$S$5:$S$54,MATCH(SMALL('Change Log'!$AH$5:$AH$54,6),'Change Log'!$AH$5:$AH$54,0))),"") | G29: =IFERROR(IF(INDEX('Change Log'!$Q$5:$Q$54,MATCH(SMALL('Change Log'!$AH$5:$AH$54,6),'Change Log'!$AH$5:$AH$54,0))="","",INDEX('Change Log'!$Q$5:$Q$54,MATCH(SMALL('Change Log'!$AH$5:$AH$54,6),'Change Log'!$AH$5:$AH$54,0))),"") | I29: =IFERROR(IF(INDEX('Change Log'!$AF$5:$AF$54,MATCH(SMALL('Change Log'!$AH$5:$AH$54,6),'Change Log'!$AH$5:$AH$54,0))="","",INDEX('Change Log'!$AF$5:$AF$54,MATCH(SMALL('Change Log'!$AH$5:$AH$54,6),'Change Log'!$AH$5:$AH$54,0))),"")
B31: Changes by type
B32: Change type | D32: Total | E32: Pending | F32: Approved | G32: Rejected / Deferred | H32: Approved schedule (days)
B33: Scope | D33: =COUNTIFS('Change Log'!$G$5:$G$54,"Scope") -> 4 | E33: =COUNTIFS('Change Log'!$G$5:$G$54,"Scope",'Change Log'!$U$5:$U$54,"Pending") -> 2 | F33: =COUNTIFS('Change Log'!$G$5:$G$54,"Scope",'Change Log'!$U$5:$U$54,"Approved")+COUNTIFS('Change Log'!$G$5:$G$54,"Scope",'Change Log'!$U$5:$U$54,"Approved with Conditions") -> 0 | G33: =COUNTIFS('Change Log'!$G$5:$G$54,"Scope",'Change Log'!$U$5:$U$54,"Rejected")+COUNTIFS('Change Log'!$G$5:$G$54,"Scope",'Change Log'!$U$5:$U$54,"Deferred") -> 2 | H33: =SUMIFS('Change Log'!$Y$5:$Y$54,'Change Log'!$G$5:$G$54,"Scope",'Change Log'!$U$5:$U$54,"Approved")+SUMIFS('Change Log'!$Y$5:$Y$54,'Change Log'!$G$5:$G$54,"Scope",'Change Log'!$U$5:$U$54,"Approved with Conditions") -> 0
B34: Schedule | D34: =COUNTIFS('Change Log'!$G$5:$G$54,"Schedule") -> 1 | E34: =COUNTIFS('Change Log'!$G$5:$G$54,"Schedule",'Change Log'!$U$5:$U$54,"Pending") -> 1 | F34: =COUNTIFS('Change Log'!$G$5:$G$54,"Schedule",'Change Log'!$U$5:$U$54,"Approved")+COUNTIFS('Change Log'!$G$5:$G$54,"Schedule",'Change Log'!$U$5:$U$54,"Approved with Conditions") -> 0 | G34: =COUNTIFS('Change Log'!$G$5:$G$54,"Schedule",'Change Log'!$U$5:$U$54,"Rejected")+COUNTIFS('Change Log'!$G$5:$G$54,"Schedule",'Change Log'!$U$5:$U$54,"Deferred") -> 0 | H34: =SUMIFS('Change Log'!$Y$5:$Y$54,'Change Log'!$G$5:$G$54,"Schedule",'Change Log'!$U$5:$U$54,"Approved")+SUMIFS('Change Log'!$Y$5:$Y$54,'Change Log'!$G$5:$G$54,"Schedule",'Change Log'!$U$5:$U$54,"Approved with Conditions") -> 0
B35: Cost / Effort | D35: =COUNTIFS('Change Log'!$G$5:$G$54,"Cost / Effort") -> 0 | E35: =COUNTIFS('Change Log'!$G$5:$G$54,"Cost / Effort",'Change Log'!$U$5:$U$54,"Pending") -> 0 | F35: =COUNTIFS('Change Log'!$G$5:$G$54,"Cost / Effort",'Change Log'!$U$5:$U$54,"Approved")+COUNTIFS('Change Log'!$G$5:$G$54,"Cost / Effort",'Change Log'!$U$5:$U$54,"Approved with Conditions") -> 0 | G35: =COUNTIFS('Change Log'!$G$5:$G$54,"Cost / Effort",'Change Log'!$U$5:$U$54,"Rejected")+COUNTIFS('Change Log'!$G$5:$G$54,"Cost / Effort",'Change Log'!$U$5:$U$54,"Deferred") -> 0 | H35: =SUMIFS('Change Log'!$Y$5:$Y$54,'Change Log'!$G$5:$G$54,"Cost / Effort",'Change Log'!$U$5:$U$54,"Approved")+SUMIFS('Change Log'!$Y$5:$Y$54,'Change Log'!$G$5:$G$54,"Cost / Effort",'Change Log'!$U$5:$U$54,"Approved with Conditions") -> 0
B36: Requirements | D36: =COUNTIFS('Change Log'!$G$5:$G$54,"Requirements") -> 2 | E36: =COUNTIFS('Change Log'!$G$5:$G$54,"Requirements",'Change Log'!$U$5:$U$54,"Pending") -> 1 | F36: =COUNTIFS('Change Log'!$G$5:$G$54,"Requirements",'Change Log'!$U$5:$U$54,"Approved")+COUNTIFS('Change Log'!$G$5:$G$54,"Requirements",'Change Log'!$U$5:$U$54,"Approved with Conditions") -> 1 | G36: =COUNTIFS('Change Log'!$G$5:$G$54,"Requirements",'Change Log'!$U$5:$U$54,"Rejected")+COUNTIFS('Change Log'!$G$5:$G$54,"Requirements",'Change Log'!$U$5:$U$54,"Deferred") -> 0 | H36: =SUMIFS('Change Log'!$Y$5:$Y$54,'Change Log'!$G$5:$G$54,"Requirements",'Change Log'!$U$5:$U$54,"Approved")+SUMIFS('Change Log'!$Y$5:$Y$54,'Change Log'!$G$5:$G$54,"Requirements",'Change Log'!$U$5:$U$54,"Approved with Conditions") -> 0
B37: Technical | D37: =COUNTIFS('Change Log'!$G$5:$G$54,"Technical") -> 1 | E37: =COUNTIFS('Change Log'!$G$5:$G$54,"Technical",'Change Log'!$U$5:$U$54,"Pending") -> 0 | F37: =COUNTIFS('Change Log'!$G$5:$G$54,"Technical",'Change Log'!$U$5:$U$54,"Approved")+COUNTIFS('Change Log'!$G$5:$G$54,"Technical",'Change Log'!$U$5:$U$54,"Approved with Conditions") -> 1 | G37: =COUNTIFS('Change Log'!$G$5:$G$54,"Technical",'Change Log'!$U$5:$U$54,"Rejected")+COUNTIFS('Change Log'!$G$5:$G$54,"Technical",'Change Log'!$U$5:$U$54,"Deferred") -> 0 | H37: =SUMIFS('Change Log'!$Y$5:$Y$54,'Change Log'!$G$5:$G$54,"Technical",'Change Log'!$U$5:$U$54,"Approved")+SUMIFS('Change Log'!$Y$5:$Y$54,'Change Log'!$G$5:$G$54,"Technical",'Change Log'!$U$5:$U$54,"Approved with Conditions") -> 4
B38: Compliance | D38: =COUNTIFS('Change Log'!$G$5:$G$54,"Compliance") -> 1 | E38: =COUNTIFS('Change Log'!$G$5:$G$54,"Compliance",'Change Log'!$U$5:$U$54,"Pending") -> 0 | F38: =COUNTIFS('Change Log'!$G$5:$G$54,"Compliance",'Change Log'!$U$5:$U$54,"Approved")+COUNTIFS('Change Log'!$G$5:$G$54,"Compliance",'Change Log'!$U$5:$U$54,"Approved with Conditions") -> 1 | G38: =COUNTIFS('Change Log'!$G$5:$G$54,"Compliance",'Change Log'!$U$5:$U$54,"Rejected")+COUNTIFS('Change Log'!$G$5:$G$54,"Compliance",'Change Log'!$U$5:$U$54,"Deferred") -> 0 | H38: =SUMIFS('Change Log'!$Y$5:$Y$54,'Change Log'!$G$5:$G$54,"Compliance",'Change Log'!$U$5:$U$54,"Approved")+SUMIFS('Change Log'!$Y$5:$Y$54,'Change Log'!$G$5:$G$54,"Compliance",'Change Log'!$U$5:$U$54,"Approved with Conditions") -> 5
B39: Total | D39: =SUM(D33:D38) -> 9 | E39: =SUM(E33:E38) -> 4 | F39: =SUM(F33:F38) -> 3 | G39: =SUM(G33:G38) -> 2 | H39: =SUM(H33:H38) -> 9

Sheet Change Log
A1: Change Request Log
A2: Merchant Payment Operations & Dispute Hub · Simulation project · Impact columns show the change as requested; Approved columns show what was actually agreed
A3: Grey columns calculate automatically. Edit white columns only; use dropdowns where provided.
A4: CR ID | B4: Title | C4: Description | D4: Requested By | E4: Date Raised | F4: Driver | G4: Change Type | H4: Baseline(s) Affected | I4: Priority | J4: Impact Assessment | K4: Schedule Impact (working days) | L4: Effort Impact (story points) | M4: Cost Impact (USD est.) | N4: Impact Rating | O4: Required Approver | P4: Options Considered | Q4: Recommendation | R4: Assessed By | S4: Decision Needed By | T4: Stage | U4: Decision | V4: Decided By | W4: Decision Date | X4: Decision Rationale / Conditions | Y4: Approved Schedule Impact (days) | Z4: Approved Effort (pts) | AA4: Approved Cost (USD) | AB4: Implementation Status | AC4: Baselines Updated | AD4: Linked Items | AE4: Days Open / to Decision | AF4: Decision Overdue? | AG4: Last Updated | AH4: Rank helper
A5: CR-01 | B5: Add fraud case management to Dispute Hub MVP | C5: Fraud operations asked to view and manage fraud cases linked to a dispute from within the hub. | D5: Fraud Operations Lead | E5: 46268 | F5: Business Request | G5: Scope | H5: MVP scope; Release plan | I5: High | J5: New screens, APIs and permissions. Depends on the fraud case-ID service, which is already late (D-07). Adding in full would push go-live beyond schedule contingency. | K5: 10 | L5: 55 | M5: 60000 | N5: =IF(A5="","",IF(G5="Compliance","High",IF(AND(K5="",L5="",M5=""),"To assess",IF(OR(N(K5)>=Cover!$C$27,N(L5)>=Cover!$D$27,N(M5)>=Cover!$E$27),"High",IF(OR(N(K5)>=Cover!$C$28,N(L5)>=Cover!$D$28,N(M5)>=Cover!$E$28),"Medium","Low"))))) -> High | O5: =IF(N5="","",IF(N5="High",Cover!$F$27,IF(N5="Medium",Cover!$F$28,Cover!$F$29))) -> Steering Committee | P5: A: Add full feature to MVP and accept go-live slip. B: Defer full feature to Phase 2. C: MVP shows a read-only fraud case reference on the dispute record; full feature in Phase 2 (about 3 points). | Q5: Option C. Meets the core need (agents can see a linked case) without moving go-live. | R5: Product Owner; Tech Lead | S5: 46290 | T5: Awaiting Decision | U5: Pending | AB5: Not Started | AD5: R-07, D-07 | AE5: =IF(OR(A5="",E5=""),"",IF(W5<>"",W5-E5,TODAY()-E5)) -> 7 | AF5: =IF(AND(U5="Pending",S5<>""),IF(TODAY()>S5,"Overdue","No"),"") -> No | AG5: 46275 | AH5: =IF(AND(A5<>"",U5="Pending"),IF(S5="",99999,S5)+ROW()/100000,"") -> 46290
A6: CR-02 | B6: Make dispute reason codes and response windows configurable | C6: Replace hard-coded reason-code logic with reference data so card network rule changes don't need a code release. | D6: Product Owner | E6: 46254 | F6: Regulatory | G6: Technical | H6: Solution design; Backlog | I6: High | J6: Lowers rework risk from network rule changes (R-01). Adds a configuration table and release process for reference data. | K6: 4 | L6: 13 | M6: 9000 | N6: =IF(A6="","",IF(G6="Compliance","High",IF(AND(K6="",L6="",M6=""),"To assess",IF(OR(N(K6)>=Cover!$C$27,N(L6)>=Cover!$D$27,N(M6)>=Cover!$E$27),"High",IF(OR(N(K6)>=Cover!$C$28,N(L6)>=Cover!$D$28,N(M6)>=Cover!$E$28),"Medium","Low"))))) -> Medium | O6: =IF(N6="","",IF(N6="High",Cover!$F$27,IF(N6="Medium",Cover!$F$28,Cover!$F$29))) -> Business Sponsor | P6: A: Keep hard-coded logic. B: Configuration table maintained by engineering. C: Admin screen so dispute ops can edit codes. | Q6: Option B for MVP; consider Option C in Phase 2. | R6: Tech Lead | S6: 46263 | T6: Implementing | U6: Approved | V6: Business Sponsor | W6: 46261 | X6: Approved as recommended. Change within schedule contingency. | Y6: 4 | Z6: 13 | AA6: 9000 | AB6: In Progress | AC6: Backlog; Solution design; RAID (R-01) | AD6: R-01, I-02 | AE6: =IF(OR(A6="",E6=""),"",IF(W6<>"",W6-E6,TODAY()-E6)) -> 7 | AF6: =IF(AND(U6="Pending",S6<>""),IF(TODAY()>S6,"Overdue","No"),"") | AG6: 46275 | AH6: =IF(AND(A6<>"",U6="Pending"),IF(S6="",99999,S6)+ROW()/100000,"")
A7: CR-03 | B7: Automated card-number redaction for evidence uploads | C7: Detect and redact full card numbers in merchant evidence files on upload. | D7: Compliance Lead | E7: 46259 | F7: Compliance | G7: Compliance | H7: Security requirements; Solution design; Backlog | I7: Critical | J7: Needed to keep evidence storage out of PCI DSS scope (R-02). Adds a processing step to uploads and requires InfoSec validation (D-03). | K7: 5 | L7: 21 | M7: 18000 | N7: =IF(A7="","",IF(G7="Compliance","High",IF(AND(K7="",L7="",M7=""),"To assess",IF(OR(N(K7)>=Cover!$C$27,N(L7)>=Cover!$D$27,N(M7)>=Cover!$E$27),"High",IF(OR(N(K7)>=Cover!$C$28,N(L7)>=Cover!$D$28,N(M7)>=Cover!$E$28),"Medium","Low"))))) -> High | O7: =IF(N7="","",IF(N7="High",Cover!$F$27,IF(N7="Medium",Cover!$F$28,Cover!$F$29))) -> Steering Committee | P7: A: Dispute ops manually review uploads. B: Automated detection and redaction on upload. C: Accept PDF uploads only, no images. | Q7: Option B. Manual review doesn't scale at peak volume; Option C blocks common evidence types such as receipt photos. | R7: Tech Lead; Compliance Lead | S7: 46270 | T7: Implementing | U7: Approved with Conditions | V7: Steering Committee | W7: 46269 | X7: Approved on condition that InfoSec validates redaction accuracy before UAT sign-off. | Y7: 5 | Z7: 21 | AA7: 18000 | AB7: In Progress | AC7: Security requirements; Backlog; Release plan; RAID (R-02) | AD7: R-02, D-03 | AE7: =IF(OR(A7="",E7=""),"",IF(W7<>"",W7-E7,TODAY()-E7)) -> 10 | AF7: =IF(AND(U7="Pending",S7<>""),IF(TODAY()>S7,"Overdue","No"),"") | AG7: 46275 | AH7: =IF(AND(A7<>"",U7="Pending"),IF(S7="",99999,S7)+ROW()/100000,"")
A8: CR-04 | B8: Add Spanish language support to merchant portal | C8: Relationship team asked for a Spanish portal for a group of pilot merchants. | D8: Merchant Relationship Manager | E8: 46262 | F8: Stakeholder Feedback | G8: Scope | H8: MVP scope (A-04: English only) | I8: Medium | J8: Translation, localization testing and content governance for all portal screens. | K8: 4 | L8: 21 | M8: 15000 | N8: =IF(A8="","",IF(G8="Compliance","High",IF(AND(K8="",L8="",M8=""),"To assess",IF(OR(N(K8)>=Cover!$C$27,N(L8)>=Cover!$D$27,N(M8)>=Cover!$E$27),"High",IF(OR(N(K8)>=Cover!$C$28,N(L8)>=Cover!$D$28,N(M8)>=Cover!$E$28),"Medium","Low"))))) -> Medium | O8: =IF(N8="","",IF(N8="High",Cover!$F$27,IF(N8="Medium",Cover!$F$28,Cover!$F$29))) -> Business Sponsor | P8: A: Add Spanish to MVP. B: Defer to Phase 2. C: Provide a Spanish PDF user guide for pilot merchants only. | Q8: Option B with Option C as an interim measure. | R8: Product Owner | S8: 46276 | T8: Closed | U8: Deferred | V8: Business Sponsor | W8: 46273 | X8: Pilot merchants confirmed an English portal with a Spanish guide is workable. Added to Phase 2 backlog. | AB8: N/A | AC8: Phase 2 backlog | AD8: A-04 | AE8: =IF(OR(A8="",E8=""),"",IF(W8<>"",W8-E8,TODAY()-E8)) -> 11 | AF8: =IF(AND(U8="Pending",S8<>""),IF(TODAY()>S8,"Overdue","No"),"") | AG8: 46275 | AH8: =IF(AND(A8<>"",U8="Pending"),IF(S8="",99999,S8)+ROW()/100000,"")
A9: CR-05 | B9: Change how dispute outcomes are reported | C9: Finance and dispute ops define partially reversed disputes differently, so the win-rate KPI can't be finalized (I-05). | D9: Finance Lead | E9: 46272 | F9: Business Request | G9: Requirements | H9: Reporting requirements; Data dictionary | I9: High | J9: Changes win-rate logic in Power BI and two reporting stories already in progress. | K9: 3 | L9: 13 | M9: 4000 | N9: =IF(A9="","",IF(G9="Compliance","High",IF(AND(K9="",L9="",M9=""),"To assess",IF(OR(N(K9)>=Cover!$C$27,N(L9)>=Cover!$D$27,N(M9)>=Cover!$E$27),"High",IF(OR(N(K9)>=Cover!$C$28,N(L9)>=Cover!$D$28,N(M9)>=Cover!$E$28),"Medium","Low"))))) -> Medium | O9: =IF(N9="","",IF(N9="High",Cover!$F$27,IF(N9="Medium",Cover!$F$28,Cover!$F$29))) -> Business Sponsor | P9: A: Finance definition (partial reversal counts as lost). B: Ops definition (partial reversal counts as won). C: Report three outcomes: won, partially won, lost. | Q9: Option C. Keeps both teams' views visible and avoids re-defining the KPI later. | R9: Business Analyst | S9: 46283 | T9: Awaiting Decision | U9: Pending | AB9: Not Started | AD9: I-05 | AE9: =IF(OR(A9="",E9=""),"",IF(W9<>"",W9-E9,TODAY()-E9)) -> 3 | AF9: =IF(AND(U9="Pending",S9<>""),IF(TODAY()>S9,"Overdue","No"),"") -> No | AG9: 46275 | AH9: =IF(AND(A9<>"",U9="Pending"),IF(S9="",99999,S9)+ROW()/100000,"") -> 46283
A10: CR-06 | B10: Run UAT in parallel with delayed penetration test | C10: InfoSec's committed pen test date is two weeks after the date needed (D-03), which would delay UAT. | D10: Project Manager | E10: 46274 | F10: Dependency Slip | G10: Schedule | H10: Release plan; UAT window | I10: High | J10: Without a change, UAT start slips and go-live is at risk. | K10: 5 | L10: 0 | M10: 12000 | N10: =IF(A10="","",IF(G10="Compliance","High",IF(AND(K10="",L10="",M10=""),"To assess",IF(OR(N(K10)>=Cover!$C$27,N(L10)>=Cover!$D$27,N(M10)>=Cover!$E$27),"High",IF(OR(N(K10)>=Cover!$C$28,N(L10)>=Cover!$D$28,N(M10)>=Cover!$E$28),"Medium","Low"))))) -> High | O10: =IF(N10="","",IF(N10="High",Cover!$F$27,IF(N10="Medium",Cover!$F$28,Cover!$F$29))) -> Steering Committee | P10: A: Move UAT one week later and compress it. B: Start UAT on non-security scope in parallel with the pen test; retest security-related stories after. C: Move go-live by two weeks. | Q10: Option B, subject to Compliance agreeing security sign-off can follow UAT start. | R10: Project Manager; QA Lead | S10: 46290 | T10: Under Assessment | U10: Pending | AB10: Not Started | AD10: D-03, R-02 | AE10: =IF(OR(A10="",E10=""),"",IF(W10<>"",W10-E10,TODAY()-E10)) -> 1 | AF10: =IF(AND(U10="Pending",S10<>""),IF(TODAY()>S10,"Overdue","No"),"") -> No | AG10: 46275 | AH10: =IF(AND(A10<>"",U10="Pending"),IF(S10="",99999,S10)+ROW()/100000,"") -> 46290
A11: CR-07 | B11: Show 'last synced' timestamp on dispute list | C11: Display when dispute data was last refreshed from the processor feed. | D11: Dispute Ops Lead | E11: 46260 | F11: Stakeholder Feedback | G11: Requirements | H11: Backlog | I11: Medium | J11: Small UI and API field change. Supports mitigation of stale-deadline risk (R-03). | K11: 0 | L11: 3 | M11: 1500 | N11: =IF(A11="","",IF(G11="Compliance","High",IF(AND(K11="",L11="",M11=""),"To assess",IF(OR(N(K11)>=Cover!$C$27,N(L11)>=Cover!$D$27,N(M11)>=Cover!$E$27),"High",IF(OR(N(K11)>=Cover!$C$28,N(L11)>=Cover!$D$28,N(M11)>=Cover!$E$28),"Medium","Low"))))) -> Low | O11: =IF(N11="","",IF(N11="High",Cover!$F$27,IF(N11="Medium",Cover!$F$28,Cover!$F$29))) -> Product Owner | P11: A: Add timestamp. B: No change. | Q11: Option A; swap with a lower-priority story of similar size. | R11: Product Owner | S11: 46263 | T11: Closed | U11: Approved | V11: Product Owner | W11: 46261 | X11: Fits in sprint capacity by swapping out a similar-sized story; no release impact. | Y11: 0 | Z11: 3 | AA11: 1500 | AB11: Verified | AC11: Backlog; RAID (R-03) | AD11: R-03 | AE11: =IF(OR(A11="",E11=""),"",IF(W11<>"",W11-E11,TODAY()-E11)) -> 1 | AF11: =IF(AND(U11="Pending",S11<>""),IF(TODAY()>S11,"Overdue","No"),"") | AG11: 46275 | AH11: =IF(AND(A11<>"",U11="Pending"),IF(S11="",99999,S11)+ROW()/100000,"")
A12: CR-08 | B12: Email nightly dispute data file to merchants | C12: Pilot merchant finance teams asked for a nightly email containing all dispute data. | D12: Merchant Relationship Manager | E12: 46255 | F12: Stakeholder Feedback | G12: Scope | H12: MVP scope; Security requirements | I12: Medium | J12: Emailing dispute data files raises data security concerns and duplicates the in-portal export already in MVP. | K12: 3 | L12: 13 | M12: 8000 | N12: =IF(A12="","",IF(G12="Compliance","High",IF(AND(K12="",L12="",M12=""),"To assess",IF(OR(N(K12)>=Cover!$C$27,N(L12)>=Cover!$D$27,N(M12)>=Cover!$E$27),"High",IF(OR(N(K12)>=Cover!$C$28,N(L12)>=Cover!$D$28,N(M12)>=Cover!$E$28),"Medium","Low"))))) -> Medium | O12: =IF(N12="","",IF(N12="High",Cover!$F$27,IF(N12="Medium",Cover!$F$28,Cover!$F$29))) -> Business Sponsor | P12: A: Nightly email file. B: Use the on-demand CSV export already in MVP. C: Reject. | Q12: Option B. | R12: Product Owner; Compliance Lead | S12: 46267 | T12: Closed | U12: Rejected | V12: Business Sponsor | W12: 46266 | X12: Email transfer of dispute data doesn't meet security requirements; merchant need is met by existing portal export. | AB12: N/A | AC12: None required | AD12: R-02 | AE12: =IF(OR(A12="",E12=""),"",IF(W12<>"",W12-E12,TODAY()-E12)) -> 11 | AF12: =IF(AND(U12="Pending",S12<>""),IF(TODAY()>S12,"Overdue","No"),"") | AG12: 46275 | AH12: =IF(AND(A12<>"",U12="Pending"),IF(S12="",99999,S12)+ROW()/100000,"")
A13: CR-09 | B13: Add SMS reminders for dispute deadlines | C13: Dispute ops asked for SMS reminders in addition to email reminders before response deadlines. | D13: Dispute Ops Lead | E13: 46274 | F13: Stakeholder Feedback | G13: Scope | H13: MVP scope | I13: Medium | J13: Impact assessment in progress; needs SMS vendor and consent review. | N13: =IF(A13="","",IF(G13="Compliance","High",IF(AND(K13="",L13="",M13=""),"To assess",IF(OR(N(K13)>=Cover!$C$27,N(L13)>=Cover!$D$27,N(M13)>=Cover!$E$27),"High",IF(OR(N(K13)>=Cover!$C$28,N(L13)>=Cover!$D$28,N(M13)>=Cover!$E$28),"Medium","Low"))))) -> To assess | O13: =IF(N13="","",IF(N13="High",Cover!$F$27,IF(N13="Medium",Cover!$F$28,Cover!$F$29))) -> Product Owner | P13: To be completed during assessment. | R13: Product Owner | S13: 46297 | T13: Under Assessment | U13: Pending | AB13: Not Started | AD13: R-03 | AE13: =IF(OR(A13="",E13=""),"",IF(W13<>"",W13-E13,TODAY()-E13)) -> 1 | AF13: =IF(AND(U13="Pending",S13<>""),IF(TODAY()>S13,"Overdue","No"),"") -> No | AG13: 46275 | AH13: =IF(AND(A13<>"",U13="Pending"),IF(S13="",99999,S13)+ROW()/100000,"") -> 46297
N14: =IF(A14="","",IF(G14="Compliance","High",IF(AND(K14="",L14="",M14=""),"To assess",IF(OR(N(K14)>=Cover!$C$27,N(L14)>=Cover!$D$27,N(M14)>=Cover!$E$27),"High",IF(OR(N(K14)>=Cover!$C$28,N(L14)>=Cover!$D$28,N(M14)>=Cover!$E$28),"Medium","Low"))))) | O14: =IF(N14="","",IF(N14="High",Cover!$F$27,IF(N14="Medium",Cover!$F$28,Cover!$F$29))) | AE14: =IF(OR(A14="",E14=""),"",IF(W14<>"",W14-E14,TODAY()-E14)) | AF14: =IF(AND(U14="Pending",S14<>""),IF(TODAY()>S14,"Overdue","No"),"") | AH14: =IF(AND(A14<>"",U14="Pending"),IF(S14="",99999,S14)+ROW()/100000,"")
N15: =IF(A15="","",IF(G15="Compliance","High",IF(AND(K15="",L15="",M15=""),"To assess",IF(OR(N(K15)>=Cover!$C$27,N(L15)>=Cover!$D$27,N(M15)>=Cover!$E$27),"High",IF(OR(N(K15)>=Cover!$C$28,N(L15)>=Cover!$D$28,N(M15)>=Cover!$E$28),"Medium","Low"))))) | O15: =IF(N15="","",IF(N15="High",Cover!$F$27,IF(N15="Medium",Cover!$F$28,Cover!$F$29))) | AE15: =IF(OR(A15="",E15=""),"",IF(W15<>"",W15-E15,TODAY()-E15)) | AF15: =IF(AND(U15="Pending",S15<>""),IF(TODAY()>S15,"Overdue","No"),"") | AH15: =IF(AND(A15<>"",U15="Pending"),IF(S15="",99999,S15)+ROW()/100000,"")
N16: =IF(A16="","",IF(G16="Compliance","High",IF(AND(K16="",L16="",M16=""),"To assess",IF(OR(N(K16)>=Cover!$C$27,N(L16)>=Cover!$D$27,N(M16)>=Cover!$E$27),"High",IF(OR(N(K16)>=Cover!$C$28,N(L16)>=Cover!$D$28,N(M16)>=Cover!$E$28),"Medium","Low"))))) | O16: =IF(N16="","",IF(N16="High",Cover!$F$27,IF(N16="Medium",Cover!$F$28,Cover!$F$29))) | AE16: =IF(OR(A16="",E16=""),"",IF(W16<>"",W16-E16,TODAY()-E16)) | AF16: =IF(AND(U16="Pending",S16<>""),IF(TODAY()>S16,"Overdue","No"),"") | AH16: =IF(AND(A16<>"",U16="Pending"),IF(S16="",99999,S16)+ROW()/100000,"")
N17: =IF(A17="","",IF(G17="Compliance","High",IF(AND(K17="",L17="",M17=""),"To assess",IF(OR(N(K17)>=Cover!$C$27,N(L17)>=Cover!$D$27,N(M17)>=Cover!$E$27),"High",IF(OR(N(K17)>=Cover!$C$28,N(L17)>=Cover!$D$28,N(M17)>=Cover!$E$28),"Medium","Low"))))) | O17: =IF(N17="","",IF(N17="High",Cover!$F$27,IF(N17="Medium",Cover!$F$28,Cover!$F$29))) | AE17: =IF(OR(A17="",E17=""),"",IF(W17<>"",W17-E17,TODAY()-E17)) | AF17: =IF(AND(U17="Pending",S17<>""),IF(TODAY()>S17,"Overdue","No"),"") | AH17: =IF(AND(A17<>"",U17="Pending"),IF(S17="",99999,S17)+ROW()/100000,"")
N18: =IF(A18="","",IF(G18="Compliance","High",IF(AND(K18="",L18="",M18=""),"To assess",IF(OR(N(K18)>=Cover!$C$27,N(L18)>=Cover!$D$27,N(M18)>=Cover!$E$27),"High",IF(OR(N(K18)>=Cover!$C$28,N(L18)>=Cover!$D$28,N(M18)>=Cover!$E$28),"Medium","Low"))))) | O18: =IF(N18="","",IF(N18="High",Cover!$F$27,IF(N18="Medium",Cover!$F$28,Cover!$F$29))) | AE18: =IF(OR(A18="",E18=""),"",IF(W18<>"",W18-E18,TODAY()-E18)) | AF18: =IF(AND(U18="Pending",S18<>""),IF(TODAY()>S18,"Overdue","No"),"") | AH18: =IF(AND(A18<>"",U18="Pending"),IF(S18="",99999,S18)+ROW()/100000,"")
N19: =IF(A19="","",IF(G19="Compliance","High",IF(AND(K19="",L19="",M19=""),"To assess",IF(OR(N(K19)>=Cover!$C$27,N(L19)>=Cover!$D$27,N(M19)>=Cover!$E$27),"High",IF(OR(N(K19)>=Cover!$C$28,N(L19)>=Cover!$D$28,N(M19)>=Cover!$E$28),"Medium","Low"))))) | O19: =IF(N19="","",IF(N19="High",Cover!$F$27,IF(N19="Medium",Cover!$F$28,Cover!$F$29))) | AE19: =IF(OR(A19="",E19=""),"",IF(W19<>"",W19-E19,TODAY()-E19)) | AF19: =IF(AND(U19="Pending",S19<>""),IF(TODAY()>S19,"Overdue","No"),"") | AH19: =IF(AND(A19<>"",U19="Pending"),IF(S19="",99999,S19)+ROW()/100000,"")
N20: =IF(A20="","",IF(G20="Compliance","High",IF(AND(K20="",L20="",M20=""),"To assess",IF(OR(N(K20)>=Cover!$C$27,N(L20)>=Cover!$D$27,N(M20)>=Cover!$E$27),"High",IF(OR(N(K20)>=Cover!$C$28,N(L20)>=Cover!$D$28,N(M20)>=Cover!$E$28),"Medium","Low"))))) | O20: =IF(N20="","",IF(N20="High",Cover!$F$27,IF(N20="Medium",Cover!$F$28,Cover!$F$29))) | AE20: =IF(OR(A20="",E20=""),"",IF(W20<>"",W20-E20,TODAY()-E20)) | AF20: =IF(AND(U20="Pending",S20<>""),IF(TODAY()>S20,"Overdue","No"),"") | AH20: =IF(AND(A20<>"",U20="Pending"),IF(S20="",99999,S20)+ROW()/100000,"")
N21: =IF(A21="","",IF(G21="Compliance","High",IF(AND(K21="",L21="",M21=""),"To assess",IF(OR(N(K21)>=Cover!$C$27,N(L21)>=Cover!$D$27,N(M21)>=Cover!$E$27),"High",IF(OR(N(K21)>=Cover!$C$28,N(L21)>=Cover!$D$28,N(M21)>=Cover!$E$28),"Medium","Low"))))) | O21: =IF(N21="","",IF(N21="High",Cover!$F$27,IF(N21="Medium",Cover!$F$28,Cover!$F$29))) | AE21: =IF(OR(A21="",E21=""),"",IF(W21<>"",W21-E21,TODAY()-E21)) | AF21: =IF(AND(U21="Pending",S21<>""),IF(TODAY()>S21,"Overdue","No"),"") | AH21: =IF(AND(A21<>"",U21="Pending"),IF(S21="",99999,S21)+ROW()/100000,"")
N22: =IF(A22="","",IF(G22="Compliance","High",IF(AND(K22="",L22="",M22=""),"To assess",IF(OR(N(K22)>=Cover!$C$27,N(L22)>=Cover!$D$27,N(M22)>=Cover!$E$27),"High",IF(OR(N(K22)>=Cover!$C$28,N(L22)>=Cover!$D$28,N(M22)>=Cover!$E$28),"Medium","Low"))))) | O22: =IF(N22="","",IF(N22="High",Cover!$F$27,IF(N22="Medium",Cover!$F$28,Cover!$F$29))) | AE22: =IF(OR(A22="",E22=""),"",IF(W22<>"",W22-E22,TODAY()-E22)) | AF22: =IF(AND(U22="Pending",S22<>""),IF(TODAY()>S22,"Overdue","No"),"") | AH22: =IF(AND(A22<>"",U22="Pending"),IF(S22="",99999,S22)+ROW()/100000,"")
N23: =IF(A23="","",IF(G23="Compliance","High",IF(AND(K23="",L23="",M23=""),"To assess",IF(OR(N(K23)>=Cover!$C$27,N(L23)>=Cover!$D$27,N(M23)>=Cover!$E$27),"High",IF(OR(N(K23)>=Cover!$C$28,N(L23)>=Cover!$D$28,N(M23)>=Cover!$E$28),"Medium","Low"))))) | O23: =IF(N23="","",IF(N23="High",Cover!$F$27,IF(N23="Medium",Cover!$F$28,Cover!$F$29))) | AE23: =IF(OR(A23="",E23=""),"",IF(W23<>"",W23-E23,TODAY()-E23)) | AF23: =IF(AND(U23="Pending",S23<>""),IF(TODAY()>S23,"Overdue","No"),"") | AH23: =IF(AND(A23<>"",U23="Pending"),IF(S23="",99999,S23)+ROW()/100000,"")
N24: =IF(A24="","",IF(G24="Compliance","High",IF(AND(K24="",L24="",M24=""),"To assess",IF(OR(N(K24)>=Cover!$C$27,N(L24)>=Cover!$D$27,N(M24)>=Cover!$E$27),"High",IF(OR(N(K24)>=Cover!$C$28,N(L24)>=Cover!$D$28,N(M24)>=Cover!$E$28),"Medium","Low"))))) | O24: =IF(N24="","",IF(N24="High",Cover!$F$27,IF(N24="Medium",Cover!$F$28,Cover!$F$29))) | AE24: =IF(OR(A24="",E24=""),"",IF(W24<>"",W24-E24,TODAY()-E24)) | AF24: =IF(AND(U24="Pending",S24<>""),IF(TODAY()>S24,"Overdue","No"),"") | AH24: =IF(AND(A24<>"",U24="Pending"),IF(S24="",99999,S24)+ROW()/100000,"")
N25: =IF(A25="","",IF(G25="Compliance","High",IF(AND(K25="",L25="",M25=""),"To assess",IF(OR(N(K25)>=Cover!$C$27,N(L25)>=Cover!$D$27,N(M25)>=Cover!$E$27),"High",IF(OR(N(K25)>=Cover!$C$28,N(L25)>=Cover!$D$28,N(M25)>=Cover!$E$28),"Medium","Low"))))) | O25: =IF(N25="","",IF(N25="High",Cover!$F$27,IF(N25="Medium",Cover!$F$28,Cover!$F$29))) | AE25: =IF(OR(A25="",E25=""),"",IF(W25<>"",W25-E25,TODAY()-E25)) | AF25: =IF(AND(U25="Pending",S25<>""),IF(TODAY()>S25,"Overdue","No"),"") | AH25: =IF(AND(A25<>"",U25="Pending"),IF(S25="",99999,S25)+ROW()/100000,"")
... N54: =IF(A54="","",IF(G54="Compliance","High",IF(AND(K54="",L54="",M54=""),"To assess",IF(OR(N(K54)>=Cover!$C$27,N(L54)>=Cover!$D$27,N(M54)>=Cover!$E$27),"High",IF(OR(N(K54)>=Cover!$C$28,N(L54)>=Cover!$D$28,N(M54)>=Cover!$E$28),"Medium","Low"))))) | O54: =IF(N54="","",IF(N54="High",Cover!$F$27,IF(N54="Medium",Cover!$F$28,Cover!$F$29))) | AE54: =IF(OR(A54="",E54=""),"",IF(W54<>"",W54-E54,TODAY()-E54)) | AF54: =IF(AND(U54="Pending",S54<>""),IF(TODAY()>S54,"Overdue","No"),"") | AH54: =IF(AND(A54<>"",U54="Pending"),IF(S54="",99999,S54)+ROW()/100000,"")
