Workbook

Sheet Cover
B2: Engagement Plan
B3: Merchant Payment Operations & Dispute Hub
B5: Document | C5: Engagement overview, stakeholder engagement, RACI, governance, communications and deliverables
B6: Version | C6: 1.0
B7: Reporting date | C7: 46275
B8: Prepared by | C8: Bhawna, Product Owner
B9: Companion documents | C9: RAID_Log, Change_Log, Product_Backlog, RTM, KPI_Definitions and Business_Case_GTM workbooks
B10: Project type | C10: Simulation / portfolio project prepared to demonstrate Product Owner practice. Not an actual client engagement; stakeholders are roles, not real people, and all dates are illustrative.
B12: Purpose
B13: Sets out how the engagement is run and how stakeholders are brought along: what we are delivering and why, who needs to be involved and how, who decides what, which forums make decisions, how we communicate, and which deliverables are due. The Dashboard highlights engagement gaps, overdue actions, upcoming governance and RACI issues.
B15: Stakeholder engagement levels
B16: Level | C16: Meaning
B17: 1 · Unaware | C17: Doesn't yet know about the engagement or how it affects them.
B18: 2 · Resistant | C18: Aware and opposed, or pushing for a conflicting outcome.
B19: 3 · Neutral | C19: Aware but not actively supporting or opposing.
B20: 4 · Supportive | C20: Aware and supports the approach and decisions.
B21: 5 · Leading | C21: Actively champions the work and influences others.
B23: Influence and interest quadrants
B24: Quadrant | C24: Approach
B25: Manage closely | C25: High influence, high interest. Involve in decisions; engage frequently and personally.
B26: Keep satisfied | C26: High influence, lower interest. Brief on decisions that affect them; avoid overloading.
B27: Keep informed | C27: Lower influence, high interest. Share progress regularly and use their feedback.
B28: Monitor | C28: Lower influence and interest. Light-touch updates; watch for changes.
B29: The threshold for 'high' is set on the Stakeholder Register tab (default 4 on a 1–5 scale).
B31: RACI
B32: Code | C32: Meaning
B33: R · Responsible | C33: Does the work. At least one per activity.
B34: A · Accountable | C34: Owns the outcome and makes the final decision. Exactly one per activity.
B35: C · Consulted | C35: Gives input before the decision; two-way conversation.
B36: I · Informed | C36: Told about the outcome; one-way communication.
B37: R/A | C37: Responsible and accountable (does the work and owns the decision).
B39: How to maintain
B40: 1. Update current engagement, last contact and next action for each stakeholder after key interactions; review weekly with the Engagement Lead.
B41: 2. Re-score influence and interest at each phase change (for example before pilot and before each wave).
B42: 3. Keep RACI in step with the Change Log decision thresholds; the check column flags rows without exactly one A.
B43: 4. Update governance next dates and communication next send dates after each meeting or send.
B44: Grey columns calculate automatically. Dashboard date windows use the reporting date above.
B46: Version history
B47: Version | C47: Date | D47: Author | E47: Change summary
B48: 1.0 | C48: 46275 | D48: Bhawna | E48: Initial engagement plan: 18 stakeholders, 18 RACI activities, 13 governance forums, 12 communications, 16 deliverables.

Sheet Dashboard
B1: Engagement Dashboard
B2: Merchant Payment Operations & Dispute Hub · Simulation project · Figures update automatically
B3: ="Reporting date: "&TEXT(Cover!$C$7,"DD-MMM-YYYY") -> Reporting date: 10-Sep-2026
B5: Summary
B6: Stakeholders | C6: Manage closely | D6: With engagement gap | E6: Resistant or unaware | F6: Overdue stakeholder actions | G6: Governance meetings in next 14 days | H6: Deliverables in review | I6: RACI rows to fix
B7: =COUNTA('Stakeholder Register'!$A$5:$A$54) -> 18 | C7: =COUNTIFS('Stakeholder Register'!$G$5:$G$54,"Manage closely") -> 5 | D7: =COUNTIFS('Stakeholder Register'!$J$5:$J$54,">0") -> 14 | E7: =COUNTIFS('Stakeholder Register'!$H$5:$H$54,"Resistant")+COUNTIFS('Stakeholder Register'!$H$5:$H$54,"Unaware") -> 3 | F7: =COUNTIFS('Stakeholder Register'!$U$5:$U$54,"Overdue") -> 1 | G7: =COUNT(Governance!$K$5:$K$34) -> 10 | H7: =COUNTIFS(Deliverables!$H$5:$H$54,"In Review") -> 4 | I7: =COUNTIFS('RACI Matrix'!$T$5:$T$40,"Needs*") -> 0
B9: Influence and interest map
B10: Influence ↑ | C10: ="Keep satisfied ("&COUNTIFS('Stakeholder Register'!$G$5:$G$54,"Keep satisfied")&")" -> Keep satisfied (4) | F10: ="Manage closely ("&COUNTIFS('Stakeholder Register'!$G$5:$G$54,"Manage closely")&")" -> Manage closely (5)
B11: Higher | C11: =IFERROR(INDEX('Stakeholder Register'!$B$5:$B$54,MATCH(SMALL('Stakeholder Register'!$W$5:$W$54,1),'Stakeholder Register'!$W$5:$W$54,0)),"") -> Steering Committee (finance, technology and risk delegates) | F11: =IFERROR(INDEX('Stakeholder Register'!$B$5:$B$54,MATCH(SMALL('Stakeholder Register'!$V$5:$V$54,1),'Stakeholder Register'!$V$5:$V$54,0)),"") -> Business Sponsor (Head of Merchant Services)
C12: =IFERROR(INDEX('Stakeholder Register'!$B$5:$B$54,MATCH(SMALL('Stakeholder Register'!$W$5:$W$54,2),'Stakeholder Register'!$W$5:$W$54,0)),"") -> InfoSec Lead | F12: =IFERROR(INDEX('Stakeholder Register'!$B$5:$B$54,MATCH(SMALL('Stakeholder Register'!$V$5:$V$54,2),'Stakeholder Register'!$V$5:$V$54,0)),"") -> Dispute Ops Lead
C13: =IFERROR(INDEX('Stakeholder Register'!$B$5:$B$54,MATCH(SMALL('Stakeholder Register'!$W$5:$W$54,3),'Stakeholder Register'!$W$5:$W$54,0)),"") -> Data Governance Lead | F13: =IFERROR(INDEX('Stakeholder Register'!$B$5:$B$54,MATCH(SMALL('Stakeholder Register'!$V$5:$V$54,3),'Stakeholder Register'!$V$5:$V$54,0)),"") -> Finance Lead
C14: =IFERROR(INDEX('Stakeholder Register'!$B$5:$B$54,MATCH(SMALL('Stakeholder Register'!$W$5:$W$54,4),'Stakeholder Register'!$W$5:$W$54,0)),"") -> Payment Processor Account Manager | F14: =IFERROR(INDEX('Stakeholder Register'!$B$5:$B$54,MATCH(SMALL('Stakeholder Register'!$V$5:$V$54,4),'Stakeholder Register'!$V$5:$V$54,0)),"") -> Compliance Lead
C15: =IFERROR(INDEX('Stakeholder Register'!$B$5:$B$54,MATCH(SMALL('Stakeholder Register'!$W$5:$W$54,5),'Stakeholder Register'!$W$5:$W$54,0)),"") | F15: =IFERROR(INDEX('Stakeholder Register'!$B$5:$B$54,MATCH(SMALL('Stakeholder Register'!$V$5:$V$54,5),'Stakeholder Register'!$V$5:$V$54,0)),"") -> Merchant Relationship Lead
C16: =IFERROR(INDEX('Stakeholder Register'!$B$5:$B$54,MATCH(SMALL('Stakeholder Register'!$W$5:$W$54,6),'Stakeholder Register'!$W$5:$W$54,0)),"") | F16: =IFERROR(INDEX('Stakeholder Register'!$B$5:$B$54,MATCH(SMALL('Stakeholder Register'!$V$5:$V$54,6),'Stakeholder Register'!$V$5:$V$54,0)),"")
C17: =IFERROR(INDEX('Stakeholder Register'!$B$5:$B$54,MATCH(SMALL('Stakeholder Register'!$W$5:$W$54,7),'Stakeholder Register'!$W$5:$W$54,0)),"") | F17: =IFERROR(INDEX('Stakeholder Register'!$B$5:$B$54,MATCH(SMALL('Stakeholder Register'!$V$5:$V$54,7),'Stakeholder Register'!$V$5:$V$54,0)),"")
C18: =IFERROR(INDEX('Stakeholder Register'!$B$5:$B$54,MATCH(SMALL('Stakeholder Register'!$W$5:$W$54,8),'Stakeholder Register'!$W$5:$W$54,0)),"") | F18: =IFERROR(INDEX('Stakeholder Register'!$B$5:$B$54,MATCH(SMALL('Stakeholder Register'!$V$5:$V$54,8),'Stakeholder Register'!$V$5:$V$54,0)),"")
C20: ="Monitor ("&COUNTIFS('Stakeholder Register'!$G$5:$G$54,"Monitor")&")" -> Monitor (6) | F20: ="Keep informed ("&COUNTIFS('Stakeholder Register'!$G$5:$G$54,"Keep informed")&")" -> Keep informed (3)
B21: Lower | C21: =IFERROR(INDEX('Stakeholder Register'!$B$5:$B$54,MATCH(SMALL('Stakeholder Register'!$Y$5:$Y$54,1),'Stakeholder Register'!$Y$5:$Y$54,0)),"") -> Legal Counsel | F21: =IFERROR(INDEX('Stakeholder Register'!$B$5:$B$54,MATCH(SMALL('Stakeholder Register'!$X$5:$X$54,1),'Stakeholder Register'!$X$5:$X$54,0)),"") -> Fraud Operations Lead
C22: =IFERROR(INDEX('Stakeholder Register'!$B$5:$B$54,MATCH(SMALL('Stakeholder Register'!$Y$5:$Y$54,2),'Stakeholder Register'!$Y$5:$Y$54,0)),"") -> IAM Team Lead | F22: =IFERROR(INDEX('Stakeholder Register'!$B$5:$B$54,MATCH(SMALL('Stakeholder Register'!$X$5:$X$54,2),'Stakeholder Register'!$X$5:$X$54,0)),"") -> Pilot merchants (10)
C23: =IFERROR(INDEX('Stakeholder Register'!$B$5:$B$54,MATCH(SMALL('Stakeholder Register'!$Y$5:$Y$54,3),'Stakeholder Register'!$Y$5:$Y$54,0)),"") -> Data Engineering Lead | F23: =IFERROR(INDEX('Stakeholder Register'!$B$5:$B$54,MATCH(SMALL('Stakeholder Register'!$X$5:$X$54,3),'Stakeholder Register'!$X$5:$X$54,0)),"") -> Delivery squads (Portal, Integration, Data)
C24: =IFERROR(INDEX('Stakeholder Register'!$B$5:$B$54,MATCH(SMALL('Stakeholder Register'!$Y$5:$Y$54,4),'Stakeholder Register'!$Y$5:$Y$54,0)),"") -> Customer Servicing Lead | F24: =IFERROR(INDEX('Stakeholder Register'!$B$5:$B$54,MATCH(SMALL('Stakeholder Register'!$X$5:$X$54,4),'Stakeholder Register'!$X$5:$X$54,0)),"")
C25: =IFERROR(INDEX('Stakeholder Register'!$B$5:$B$54,MATCH(SMALL('Stakeholder Register'!$Y$5:$Y$54,5),'Stakeholder Register'!$Y$5:$Y$54,0)),"") -> Marketing and Merchant Communications Lead | F25: =IFERROR(INDEX('Stakeholder Register'!$B$5:$B$54,MATCH(SMALL('Stakeholder Register'!$X$5:$X$54,5),'Stakeholder Register'!$X$5:$X$54,0)),"")
C26: =IFERROR(INDEX('Stakeholder Register'!$B$5:$B$54,MATCH(SMALL('Stakeholder Register'!$Y$5:$Y$54,6),'Stakeholder Register'!$Y$5:$Y$54,0)),"") -> Document Storage Vendor | F26: =IFERROR(INDEX('Stakeholder Register'!$B$5:$B$54,MATCH(SMALL('Stakeholder Register'!$X$5:$X$54,6),'Stakeholder Register'!$X$5:$X$54,0)),"")
C27: =IFERROR(INDEX('Stakeholder Register'!$B$5:$B$54,MATCH(SMALL('Stakeholder Register'!$Y$5:$Y$54,7),'Stakeholder Register'!$Y$5:$Y$54,0)),"") | F27: =IFERROR(INDEX('Stakeholder Register'!$B$5:$B$54,MATCH(SMALL('Stakeholder Register'!$X$5:$X$54,7),'Stakeholder Register'!$X$5:$X$54,0)),"")
C28: =IFERROR(INDEX('Stakeholder Register'!$B$5:$B$54,MATCH(SMALL('Stakeholder Register'!$Y$5:$Y$54,8),'Stakeholder Register'!$Y$5:$Y$54,0)),"") | F28: =IFERROR(INDEX('Stakeholder Register'!$B$5:$B$54,MATCH(SMALL('Stakeholder Register'!$X$5:$X$54,8),'Stakeholder Register'!$X$5:$X$54,0)),"")
C29: Lower interest | F29: Interest → | G29: Higher interest
B31: Biggest engagement gaps (gap × influence)
B32: ID | C32: Stakeholder | D32: Current | E32: Desired | F32: Gap | G32: Next action | I32: Due
B33: =IFERROR(INDEX('Stakeholder Register'!$A$5:$A$54,MATCH(LARGE('Stakeholder Register'!$Z$5:$Z$54,1),'Stakeholder Register'!$Z$5:$Z$54,0)),"") -> SH-05 | C33: =IFERROR(INDEX('Stakeholder Register'!$B$5:$B$54,MATCH(LARGE('Stakeholder Register'!$Z$5:$Z$54,1),'Stakeholder Register'!$Z$5:$Z$54,0)),"") -> Fraud Operations Lead | D33: =IFERROR(INDEX('Stakeholder Register'!$H$5:$H$54,MATCH(LARGE('Stakeholder Register'!$Z$5:$Z$54,1),'Stakeholder Register'!$Z$5:$Z$54,0)),"") -> Resistant | E33: =IFERROR(INDEX('Stakeholder Register'!$I$5:$I$54,MATCH(LARGE('Stakeholder Register'!$Z$5:$Z$54,1),'Stakeholder Register'!$Z$5:$Z$54,0)),"") -> Supportive | F33: =IFERROR(INDEX('Stakeholder Register'!$J$5:$J$54,MATCH(LARGE('Stakeholder Register'!$Z$5:$Z$54,1),'Stakeholder Register'!$Z$5:$Z$54,0)),"") -> 2 | G33: =IFERROR(INDEX('Stakeholder Register'!$S$5:$S$54,MATCH(LARGE('Stakeholder Register'!$Z$5:$Z$54,1),'Stakeholder Register'!$Z$5:$Z$54,0)),"") -> Share CR-01 impact assessment and Phase 2 roadmap slot | I33: =IFERROR(INDEX('Stakeholder Register'!$T$5:$T$54,MATCH(LARGE('Stakeholder Register'!$Z$5:$Z$54,1),'Stakeholder Register'!$Z$5:$Z$54,0)),"") -> 46276
B34: =IFERROR(INDEX('Stakeholder Register'!$A$5:$A$54,MATCH(LARGE('Stakeholder Register'!$Z$5:$Z$54,2),'Stakeholder Register'!$Z$5:$Z$54,0)),"") -> SH-14 | C34: =IFERROR(INDEX('Stakeholder Register'!$B$5:$B$54,MATCH(LARGE('Stakeholder Register'!$Z$5:$Z$54,2),'Stakeholder Register'!$Z$5:$Z$54,0)),"") -> Marketing and Merchant Communications Lead | D34: =IFERROR(INDEX('Stakeholder Register'!$H$5:$H$54,MATCH(LARGE('Stakeholder Register'!$Z$5:$Z$54,2),'Stakeholder Register'!$Z$5:$Z$54,0)),"") -> Unaware | E34: =IFERROR(INDEX('Stakeholder Register'!$I$5:$I$54,MATCH(LARGE('Stakeholder Register'!$Z$5:$Z$54,2),'Stakeholder Register'!$Z$5:$Z$54,0)),"") -> Supportive | F34: =IFERROR(INDEX('Stakeholder Register'!$J$5:$J$54,MATCH(LARGE('Stakeholder Register'!$Z$5:$Z$54,2),'Stakeholder Register'!$Z$5:$Z$54,0)),"") -> 3 | G34: =IFERROR(INDEX('Stakeholder Register'!$S$5:$S$54,MATCH(LARGE('Stakeholder Register'!$Z$5:$Z$54,2),'Stakeholder Register'!$Z$5:$Z$54,0)),"") -> First briefing on GTM plan | I34: =IFERROR(INDEX('Stakeholder Register'!$T$5:$T$54,MATCH(LARGE('Stakeholder Register'!$Z$5:$Z$54,2),'Stakeholder Register'!$Z$5:$Z$54,0)),"") -> 46300
B35: =IFERROR(INDEX('Stakeholder Register'!$A$5:$A$54,MATCH(LARGE('Stakeholder Register'!$Z$5:$Z$54,3),'Stakeholder Register'!$Z$5:$Z$54,0)),"") -> SH-17 | C35: =IFERROR(INDEX('Stakeholder Register'!$B$5:$B$54,MATCH(LARGE('Stakeholder Register'!$Z$5:$Z$54,3),'Stakeholder Register'!$Z$5:$Z$54,0)),"") -> Pilot merchants (10) | D35: =IFERROR(INDEX('Stakeholder Register'!$H$5:$H$54,MATCH(LARGE('Stakeholder Register'!$Z$5:$Z$54,3),'Stakeholder Register'!$Z$5:$Z$54,0)),"") -> Unaware | E35: =IFERROR(INDEX('Stakeholder Register'!$I$5:$I$54,MATCH(LARGE('Stakeholder Register'!$Z$5:$Z$54,3),'Stakeholder Register'!$Z$5:$Z$54,0)),"") -> Supportive | F35: =IFERROR(INDEX('Stakeholder Register'!$J$5:$J$54,MATCH(LARGE('Stakeholder Register'!$Z$5:$Z$54,3),'Stakeholder Register'!$Z$5:$Z$54,0)),"") -> 3 | G35: =IFERROR(INDEX('Stakeholder Register'!$S$5:$S$54,MATCH(LARGE('Stakeholder Register'!$Z$5:$Z$54,3),'Stakeholder Register'!$Z$5:$Z$54,0)),"") -> Send pilot invitations once terms are approved | I35: =IFERROR(INDEX('Stakeholder Register'!$T$5:$T$54,MATCH(LARGE('Stakeholder Register'!$Z$5:$Z$54,3),'Stakeholder Register'!$Z$5:$Z$54,0)),"") -> 46328
B36: =IFERROR(INDEX('Stakeholder Register'!$A$5:$A$54,MATCH(LARGE('Stakeholder Register'!$Z$5:$Z$54,4),'Stakeholder Register'!$Z$5:$Z$54,0)),"") -> SH-01 | C36: =IFERROR(INDEX('Stakeholder Register'!$B$5:$B$54,MATCH(LARGE('Stakeholder Register'!$Z$5:$Z$54,4),'Stakeholder Register'!$Z$5:$Z$54,0)),"") -> Business Sponsor (Head of Merchant Services) | D36: =IFERROR(INDEX('Stakeholder Register'!$H$5:$H$54,MATCH(LARGE('Stakeholder Register'!$Z$5:$Z$54,4),'Stakeholder Register'!$Z$5:$Z$54,0)),"") -> Supportive | E36: =IFERROR(INDEX('Stakeholder Register'!$I$5:$I$54,MATCH(LARGE('Stakeholder Register'!$Z$5:$Z$54,4),'Stakeholder Register'!$Z$5:$Z$54,0)),"") -> Leading | F36: =IFERROR(INDEX('Stakeholder Register'!$J$5:$J$54,MATCH(LARGE('Stakeholder Register'!$Z$5:$Z$54,4),'Stakeholder Register'!$Z$5:$Z$54,0)),"") -> 1 | G36: =IFERROR(INDEX('Stakeholder Register'!$S$5:$S$54,MATCH(LARGE('Stakeholder Register'!$Z$5:$Z$54,4),'Stakeholder Register'!$Z$5:$Z$54,0)),"") -> Pre-wire CR-01 Option C and business case before steering committee | I36: =IFERROR(INDEX('Stakeholder Register'!$T$5:$T$54,MATCH(LARGE('Stakeholder Register'!$Z$5:$Z$54,4),'Stakeholder Register'!$Z$5:$Z$54,0)),"") -> 46279
B37: =IFERROR(INDEX('Stakeholder Register'!$A$5:$A$54,MATCH(LARGE('Stakeholder Register'!$Z$5:$Z$54,5),'Stakeholder Register'!$Z$5:$Z$54,0)),"") -> SH-02 | C37: =IFERROR(INDEX('Stakeholder Register'!$B$5:$B$54,MATCH(LARGE('Stakeholder Register'!$Z$5:$Z$54,5),'Stakeholder Register'!$Z$5:$Z$54,0)),"") -> Steering Committee (finance, technology and risk delegates) | D37: =IFERROR(INDEX('Stakeholder Register'!$H$5:$H$54,MATCH(LARGE('Stakeholder Register'!$Z$5:$Z$54,5),'Stakeholder Register'!$Z$5:$Z$54,0)),"") -> Neutral | E37: =IFERROR(INDEX('Stakeholder Register'!$I$5:$I$54,MATCH(LARGE('Stakeholder Register'!$Z$5:$Z$54,5),'Stakeholder Register'!$Z$5:$Z$54,0)),"") -> Supportive | F37: =IFERROR(INDEX('Stakeholder Register'!$J$5:$J$54,MATCH(LARGE('Stakeholder Register'!$Z$5:$Z$54,5),'Stakeholder Register'!$Z$5:$Z$54,0)),"") -> 1 | G37: =IFERROR(INDEX('Stakeholder Register'!$S$5:$S$54,MATCH(LARGE('Stakeholder Register'!$Z$5:$Z$54,5),'Stakeholder Register'!$Z$5:$Z$54,0)),"") -> Circulate pre-read two days before next meeting | I37: =IFERROR(INDEX('Stakeholder Register'!$T$5:$T$54,MATCH(LARGE('Stakeholder Register'!$Z$5:$Z$54,5),'Stakeholder Register'!$Z$5:$Z$54,0)),"") -> 46287
B38: =IFERROR(INDEX('Stakeholder Register'!$A$5:$A$54,MATCH(LARGE('Stakeholder Register'!$Z$5:$Z$54,6),'Stakeholder Register'!$Z$5:$Z$54,0)),"") -> SH-03 | C38: =IFERROR(INDEX('Stakeholder Register'!$B$5:$B$54,MATCH(LARGE('Stakeholder Register'!$Z$5:$Z$54,6),'Stakeholder Register'!$Z$5:$Z$54,0)),"") -> Dispute Ops Lead | D38: =IFERROR(INDEX('Stakeholder Register'!$H$5:$H$54,MATCH(LARGE('Stakeholder Register'!$Z$5:$Z$54,6),'Stakeholder Register'!$Z$5:$Z$54,0)),"") -> Supportive | E38: =IFERROR(INDEX('Stakeholder Register'!$I$5:$I$54,MATCH(LARGE('Stakeholder Register'!$Z$5:$Z$54,6),'Stakeholder Register'!$Z$5:$Z$54,0)),"") -> Leading | F38: =IFERROR(INDEX('Stakeholder Register'!$J$5:$J$54,MATCH(LARGE('Stakeholder Register'!$Z$5:$Z$54,6),'Stakeholder Register'!$Z$5:$Z$54,0)),"") -> 1 | G38: =IFERROR(INDEX('Stakeholder Register'!$S$5:$S$54,MATCH(LARGE('Stakeholder Register'!$Z$5:$Z$54,6),'Stakeholder Register'!$Z$5:$Z$54,0)),"") -> Confirm UAT SME bookings for November | I38: =IFERROR(INDEX('Stakeholder Register'!$T$5:$T$54,MATCH(LARGE('Stakeholder Register'!$Z$5:$Z$54,6),'Stakeholder Register'!$Z$5:$Z$54,0)),"") -> 46283
B40: Governance in the next 14 days
B41: Date | C41: Forum | E41: Chair | F41: Decisions and outputs | I41: Days until
B42: =IFERROR(INDEX(Governance!$I$5:$I$34,MATCH(SMALL(Governance!$K$5:$K$34,1),Governance!$K$5:$K$34,0)),"") -> 46276 | C42: =IFERROR(INDEX(Governance!$A$5:$A$34,MATCH(SMALL(Governance!$K$5:$K$34,1),Governance!$K$5:$K$34,0)),"") -> Sprint review | E42: =IFERROR(INDEX(Governance!$C$5:$C$34,MATCH(SMALL(Governance!$K$5:$K$34,1),Governance!$K$5:$K$34,0)),"") -> Product Owner | F42: =IFERROR(INDEX(Governance!$H$5:$H$34,MATCH(SMALL(Governance!$K$5:$K$34,1),Governance!$K$5:$K$34,0)),"") -> Accepted stories; backlog changes | I42: =IFERROR(INDEX(Governance!$J$5:$J$34,MATCH(SMALL(Governance!$K$5:$K$34,1),Governance!$K$5:$K$34,0)),"") -> 1
B43: =IFERROR(INDEX(Governance!$I$5:$I$34,MATCH(SMALL(Governance!$K$5:$K$34,2),Governance!$K$5:$K$34,0)),"") -> 46279 | C43: =IFERROR(INDEX(Governance!$A$5:$A$34,MATCH(SMALL(Governance!$K$5:$K$34,2),Governance!$K$5:$K$34,0)),"") -> Sponsor 1:1 | E43: =IFERROR(INDEX(Governance!$C$5:$C$34,MATCH(SMALL(Governance!$K$5:$K$34,2),Governance!$K$5:$K$34,0)),"") -> Engagement Lead | F43: =IFERROR(INDEX(Governance!$H$5:$H$34,MATCH(SMALL(Governance!$K$5:$K$34,2),Governance!$K$5:$K$34,0)),"") -> Medium-impact change decisions; escalation support | I43: =IFERROR(INDEX(Governance!$J$5:$J$34,MATCH(SMALL(Governance!$K$5:$K$34,2),Governance!$K$5:$K$34,0)),"") -> 4
B44: =IFERROR(INDEX(Governance!$I$5:$I$34,MATCH(SMALL(Governance!$K$5:$K$34,3),Governance!$K$5:$K$34,0)),"") -> 46279 | C44: =IFERROR(INDEX(Governance!$A$5:$A$34,MATCH(SMALL(Governance!$K$5:$K$34,3),Governance!$K$5:$K$34,0)),"") -> Sprint planning | E44: =IFERROR(INDEX(Governance!$C$5:$C$34,MATCH(SMALL(Governance!$K$5:$K$34,3),Governance!$K$5:$K$34,0)),"") -> Product Owner | F44: =IFERROR(INDEX(Governance!$H$5:$H$34,MATCH(SMALL(Governance!$K$5:$K$34,3),Governance!$K$5:$K$34,0)),"") -> Sprint goal and committed items | I44: =IFERROR(INDEX(Governance!$J$5:$J$34,MATCH(SMALL(Governance!$K$5:$K$34,3),Governance!$K$5:$K$34,0)),"") -> 4
B45: =IFERROR(INDEX(Governance!$I$5:$I$34,MATCH(SMALL(Governance!$K$5:$K$34,4),Governance!$K$5:$K$34,0)),"") -> 46280 | C45: =IFERROR(INDEX(Governance!$A$5:$A$34,MATCH(SMALL(Governance!$K$5:$K$34,4),Governance!$K$5:$K$34,0)),"") -> Backlog refinement | E45: =IFERROR(INDEX(Governance!$C$5:$C$34,MATCH(SMALL(Governance!$K$5:$K$34,4),Governance!$K$5:$K$34,0)),"") -> Product Owner | F45: =IFERROR(INDEX(Governance!$H$5:$H$34,MATCH(SMALL(Governance!$K$5:$K$34,4),Governance!$K$5:$K$34,0)),"") -> Refined and estimated stories | I45: =IFERROR(INDEX(Governance!$J$5:$J$34,MATCH(SMALL(Governance!$K$5:$K$34,4),Governance!$K$5:$K$34,0)),"") -> 5
...

Sheet Engagement Overview
A1: Engagement Overview
A2: Merchant Payment Operations & Dispute Hub · Simulation project
A4: Engagement summary
A5: Topic | B5: Summary
A6: Client context | B6: Merchant services division of a card payments provider (illustrative), supporting about 25,000 active merchants.
A7: Problem | B7: Merchants manage disputes by email and spreadsheets. Deadlines are missed, evidence is chased manually, ops handling time is high and settlement changes are hard to explain.
A8: Objectives | B8: 1. Give merchants self-service dispute tracking and evidence submission. 2. Cut ops handling time and missed-deadline losses. 3. Keep card data out of evidence storage. 4. Give ops and finance one trusted set of dispute numbers.
A9: In scope (MVP) | B9: Merchant portal (inbox, dispute detail, evidence upload and submission), processor integration, reminders, settlement visibility, ops work queue, reporting, servicing status API.
A10: Out of scope | B10: Fraud case management (Phase 2, CR-01), Spanish portal (Phase 2, CR-04), marketplace sub-merchant model, SMS reminders pending CR-09.
A11: Delivery approach | B11: Agile delivery in two-week sprints with a pilot-led rollout; governance through sponsor 1:1s, fortnightly steering committee and weekly RAID and change review.
A12: Key constraints | B12: Q4 dispute peak limits SME time (R-06); holiday change freeze after go-live; security and compliance gates before launch (D-03, CR-03).
A13: Success criteria | B13: MVP live by 11-Dec-2026; pilot exit gates met; base-case KPI targets by mid-2027 (KPI-03 on-time response 95%, KPI-05 handling time 25 min, KPI-06 portal share 70%).
A15: Phases
A16: Phase | B16: Dates | C16: Focus | E16: Key outputs
A17: Discovery | B17: Jun – Jul 2026 | C17: Merchant and ops research; problem and opportunity sizing | E17: Discovery findings; MVP scope baseline
A18: Mobilization and design | B18: Jul – Aug 2026 | C18: Team setup, solution design, governance, RAID and change control | E18: Solution design; RAID and change logs; engagement plan
A19: Build | B19: 20-Jul – 04-Dec 2026 | C19: Sprints 1–10; SIT, security and accessibility testing; UAT | E19: Working MVP; RTM; KPI definitions; business case
A20: Launch and pilot | B20: Dec 2026 – Mar 2027 | C20: Go-live, hypercare, 10-merchant pilot | E20: Go-live readiness pack; pilot results report
A21: Scale | B21: Mar – Dec 2027 | C21: Wave 1, Wave 2, general availability; email intake retirement | E21: Wave go / no-go packs; benefits tracking
A23: Engagement team model
A24: Role | B24: Organization | C24: Responsibilities | F24: Allocation
A25: Business Sponsor | B25: Client | C25: Funding, priorities, Medium-impact decisions, sponsor escalations | F25: As needed
A26: Engagement Lead | B26: Delivery partner | C26: Overall delivery accountability, sponsor relationship, commercial and quality oversight | F26: Part time
A27: Product Owner | B27: Delivery partner | C27: Product vision, backlog ownership, stakeholder alignment, acceptance, KPIs and business case | F27: Full time
A28: Project Manager | B28: Delivery partner | C28: Plan, RAID, change control, status reporting, vendor coordination | F28: Part time
A29: Business Analyst | B29: Delivery partner | C29: Requirements, process mapping, acceptance criteria, UAT support | F29: Full time
A30: Tech Lead | B30: Delivery partner | C30: Solution design, engineering delivery, technical risk | F30: Full time
A31: Delivery squads (Portal, Integration, Data) | B31: Delivery partner | C31: Build, test and release MVP features | F31: Full time
A32: QA Lead | B32: Delivery partner | C32: Test strategy, traceability, UAT coordination | F32: Full time
A33: UX Designer | B33: Delivery partner | C33: Research, designs, accessibility | F33: Part time
A34: Client SMEs (Dispute Ops, Finance, Compliance, Servicing) | B34: Client | C34: Process knowledge, requirement sign-off, UAT execution, readiness | F34: Part time (bookings agreed)

Sheet Stakeholder Register
A1: Stakeholder Register
A2: Merchant Payment Operations & Dispute Hub · Simulation project · Stakeholders are roles, not named individuals
A3: High influence / interest threshold (1–5): | E3: 4 | G3: Grey columns calculate automatically. Engagement gap = desired level − current level.
A4: ID | B4: Stakeholder | C4: Group | D4: Type | E4: Influence (1-5) | F4: Interest (1-5) | G4: Quadrant | H4: Current engagement | I4: Desired engagement | J4: Gap | K4: Priority score | L4: Interests and concerns | M4: Engagement strategy | N4: Relationship owner | O4: Frequency | P4: Channel | Q4: Linked items | R4: Last contact | S4: Next action | T4: Next action date | U4: Action overdue? | V4: h_mc | W4: h_ks | X4: h_ki | Y4: h_mon | Z4: h_gap
A5: SH-01 | B5: Business Sponsor (Head of Merchant Services) | C5: Merchant Services leadership | D5: Client | E5: 5 | F5: 4 | G5: =IF(A5="","",IF(AND(E5>=$E$3,F5>=$E$3),"Manage closely",IF(E5>=$E$3,"Keep satisfied",IF(F5>=$E$3,"Keep informed","Monitor")))) -> Manage closely | H5: Supportive | I5: Leading | J5: =IF(OR(A5="",H5="",I5=""),"",IF(I5="Unaware",1,IF(I5="Resistant",2,IF(I5="Neutral",3,IF(I5="Supportive",4,IF(I5="Leading",5,0)))))-IF(H5="Unaware",1,IF(H5="Resistant",2,IF(H5="Neutral",3,IF(H5="Supportive",4,IF(H5="Leading",5,0)))))) -> 1 | K5: =IF(J5="","",J5*E5) -> 5 | L5: Return on investment, go-live date, merchant experience, visible progress for leadership. | M5: Weekly 1:1; pre-wire every steering committee decision; share business case scenarios early so there are no surprises. | N5: Engagement Lead | O5: Weekly | P5: 1:1 meeting | Q5: CR-01, CR-05, Business case | R5: 46272 | S5: Pre-wire CR-01 Option C and business case before steering committee | T5: 46279 | U5: =IF(OR(A5="",T5=""),"",IF(T5<Cover!$C$7,"Overdue","No")) -> No | V5: =IF(G5="Manage closely",ROW(),"") -> 5 | W5: =IF(G5="Keep satisfied",ROW(),"") | X5: =IF(G5="Keep informed",ROW(),"") | Y5: =IF(G5="Monitor",ROW(),"") | Z5: =IF(OR(J5="",N(J5)<=0),"",K5+(1000-ROW())/100000) -> 5.00995
A6: SH-02 | B6: Steering Committee (finance, technology and risk delegates) | C6: Executive governance | D6: Client | E6: 5 | F6: 3 | G6: =IF(A6="","",IF(AND(E6>=$E$3,F6>=$E$3),"Manage closely",IF(E6>=$E$3,"Keep satisfied",IF(F6>=$E$3,"Keep informed","Monitor")))) -> Keep satisfied | H6: Neutral | I6: Supportive | J6: =IF(OR(A6="",H6="",I6=""),"",IF(I6="Unaware",1,IF(I6="Resistant",2,IF(I6="Neutral",3,IF(I6="Supportive",4,IF(I6="Leading",5,0)))))-IF(H6="Unaware",1,IF(H6="Resistant",2,IF(H6="Neutral",3,IF(H6="Supportive",4,IF(H6="Leading",5,0)))))) -> 1 | K6: =IF(J6="","",J6*E6) -> 5 | L6: Cost against contingency, security and compliance risk, delivery confidence. | M6: Fortnightly decision papers with clear options and recommendation; show conservative case openly; escalate only decisions that need them. | N6: Product Owner | O6: Fortnightly | P6: Steering committee | Q6: D-03, CR-06, Business case | R6: 46275 | S6: Circulate pre-read two days before next meeting | T6: 46287 | U6: =IF(OR(A6="",T6=""),"",IF(T6<Cover!$C$7,"Overdue","No")) -> No | V6: =IF(G6="Manage closely",ROW(),"") | W6: =IF(G6="Keep satisfied",ROW(),"") -> 6 | X6: =IF(G6="Keep informed",ROW(),"") | Y6: =IF(G6="Monitor",ROW(),"") | Z6: =IF(OR(J6="",N(J6)<=0),"",K6+(1000-ROW())/100000) -> 5.00994
A7: SH-03 | B7: Dispute Ops Lead | C7: Dispute Operations | D7: Client | E7: 4 | F7: 5 | G7: =IF(A7="","",IF(AND(E7>=$E$3,F7>=$E$3),"Manage closely",IF(E7>=$E$3,"Keep satisfied",IF(F7>=$E$3,"Keep informed","Monitor")))) -> Manage closely | H7: Supportive | I7: Leading | J7: =IF(OR(A7="",H7="",I7=""),"",IF(I7="Unaware",1,IF(I7="Resistant",2,IF(I7="Neutral",3,IF(I7="Supportive",4,IF(I7="Leading",5,0)))))-IF(H7="Unaware",1,IF(H7="Resistant",2,IF(H7="Neutral",3,IF(H7="Supportive",4,IF(H7="Leading",5,0)))))) -> 1 | K7: =IF(J7="","",J7*E7) -> 4 | L7: Team workload during Q4 peak, handling time, reliable deadlines for merchants. | M7: Co-design sessions; make them owner of UAT scenarios and ops readiness; protect SME time during peak (R-06). | N7: Product Owner | O7: Weekly | P7: Working session | Q7: R-06, KPI-05, I-02 | R7: 46274 | S7: Confirm UAT SME bookings for November | T7: 46283 | U7: =IF(OR(A7="",T7=""),"",IF(T7<Cover!$C$7,"Overdue","No")) -> No | V7: =IF(G7="Manage closely",ROW(),"") -> 7 | W7: =IF(G7="Keep satisfied",ROW(),"") | X7: =IF(G7="Keep informed",ROW(),"") | Y7: =IF(G7="Monitor",ROW(),"") | Z7: =IF(OR(J7="",N(J7)<=0),"",K7+(1000-ROW())/100000) -> 4.00993
A8: SH-04 | B8: Finance Lead | C8: Finance | D8: Client | E8: 4 | F8: 4 | G8: =IF(A8="","",IF(AND(E8>=$E$3,F8>=$E$3),"Manage closely",IF(E8>=$E$3,"Keep satisfied",IF(F8>=$E$3,"Keep informed","Monitor")))) -> Manage closely | H8: Neutral | I8: Supportive | J8: =IF(OR(A8="",H8="",I8=""),"",IF(I8="Unaware",1,IF(I8="Resistant",2,IF(I8="Neutral",3,IF(I8="Supportive",4,IF(I8="Leading",5,0)))))-IF(H8="Unaware",1,IF(H8="Resistant",2,IF(H8="Neutral",3,IF(H8="Supportive",4,IF(H8="Leading",5,0)))))) -> 1 | K8: =IF(J8="","",J8*E8) -> 4 | L8: How dispute outcomes and win rate are defined; whether ops savings are cashable; reconciliation accuracy. | M8: 1:1 using the outcome definitions worked example; involve in KPI sign-off; agree ops capacity treatment before Wave 1. | N8: Product Owner | O8: Weekly | P8: 1:1 meeting | Q8: CR-05, I-05, LR-17 | R8: 46273 | S8: Walk through outcome definitions worked example | T8: 46280 | U8: =IF(OR(A8="",T8=""),"",IF(T8<Cover!$C$7,"Overdue","No")) -> No | V8: =IF(G8="Manage closely",ROW(),"") -> 8 | W8: =IF(G8="Keep satisfied",ROW(),"") | X8: =IF(G8="Keep informed",ROW(),"") | Y8: =IF(G8="Monitor",ROW(),"") | Z8: =IF(OR(J8="",N(J8)<=0),"",K8+(1000-ROW())/100000) -> 4.00992
A9: SH-05 | B9: Fraud Operations Lead | C9: Fraud Operations | D9: Client | E9: 3 | F9: 4 | G9: =IF(A9="","",IF(AND(E9>=$E$3,F9>=$E$3),"Manage closely",IF(E9>=$E$3,"Keep satisfied",IF(F9>=$E$3,"Keep informed","Monitor")))) -> Keep informed | H9: Resistant | I9: Supportive | J9: =IF(OR(A9="",H9="",I9=""),"",IF(I9="Unaware",1,IF(I9="Resistant",2,IF(I9="Neutral",3,IF(I9="Supportive",4,IF(I9="Leading",5,0)))))-IF(H9="Unaware",1,IF(H9="Resistant",2,IF(H9="Neutral",3,IF(H9="Supportive",4,IF(H9="Leading",5,0)))))) -> 2 | K9: =IF(J9="","",J9*E9) -> 6 | L9: Wants fraud case management in the MVP; worried fraud context will be missed on disputes. | M9: Explain CR-01 options and impact; offer Option C read-only reference in MVP with a Phase 2 roadmap commitment; invite to sprint review. | N9: Product Owner | O9: Fortnightly | P9: Working session | Q9: CR-01, D-07, R-07 | R9: 46268 | S9: Share CR-01 impact assessment and Phase 2 roadmap slot | T9: 46276 | U9: =IF(OR(A9="",T9=""),"",IF(T9<Cover!$C$7,"Overdue","No")) -> No | V9: =IF(G9="Manage closely",ROW(),"") | W9: =IF(G9="Keep satisfied",ROW(),"") | X9: =IF(G9="Keep informed",ROW(),"") -> 9 | Y9: =IF(G9="Monitor",ROW(),"") | Z9: =IF(OR(J9="",N(J9)<=0),"",K9+(1000-ROW())/100000) -> 6.00991
A10: SH-06 | B10: Compliance Lead | C10: Compliance | D10: Client | E10: 5 | F10: 4 | G10: =IF(A10="","",IF(AND(E10>=$E$3,F10>=$E$3),"Manage closely",IF(E10>=$E$3,"Keep satisfied",IF(F10>=$E$3,"Keep informed","Monitor")))) -> Manage closely | H10: Supportive | I10: Supportive | J10: =IF(OR(A10="",H10="",I10=""),"",IF(I10="Unaware",1,IF(I10="Resistant",2,IF(I10="Neutral",3,IF(I10="Supportive",4,IF(I10="Leading",5,0)))))-IF(H10="Unaware",1,IF(H10="Resistant",2,IF(H10="Neutral",3,IF(H10="Supportive",4,IF(H10="Leading",5,0)))))) -> 0 | K10: =IF(J10="","",J10*E10) -> 0 | L10: PCI DSS scope, card data exposure, evidence retention, audit trail. | M10: Fortnightly checkpoint using the RTM control view; share evidence gaps early; no surprises at go-live. | N10: Product Owner | O10: Fortnightly | P10: Checkpoint meeting | Q10: R-02, CR-03, A-07, CTL-09 | R10: 46267 | S10: Review CTL-09 retention gap and A-07 timeline | T10: 46281 | U10: =IF(OR(A10="",T10=""),"",IF(T10<Cover!$C$7,"Overdue","No")) -> No | V10: =IF(G10="Manage closely",ROW(),"") -> 10 | W10: =IF(G10="Keep satisfied",ROW(),"") | X10: =IF(G10="Keep informed",ROW(),"") | Y10: =IF(G10="Monitor",ROW(),"") | Z10: =IF(OR(J10="",N(J10)<=0),"",K10+(1000-ROW())/100000)
A11: SH-07 | B11: InfoSec Lead | C11: Information Security | D11: Client | E11: 4 | F11: 3 | G11: =IF(A11="","",IF(AND(E11>=$E$3,F11>=$E$3),"Manage closely",IF(E11>=$E$3,"Keep satisfied",IF(F11>=$E$3,"Keep informed","Monitor")))) -> Keep satisfied | H11: Neutral | I11: Supportive | J11: =IF(OR(A11="",H11="",I11=""),"",IF(I11="Unaware",1,IF(I11="Resistant",2,IF(I11="Neutral",3,IF(I11="Supportive",4,IF(I11="Leading",5,0)))))-IF(H11="Unaware",1,IF(H11="Resistant",2,IF(H11="Neutral",3,IF(H11="Supportive",4,IF(H11="Leading",5,0)))))) -> 1 | K11: =IF(J11="","",J11*E11) -> 4 | L11: Pen test capacity, redaction validation effort, vendor security assessments. | M11: Share test scope and dates early; ask sponsor to support priority pen test slot; agree redaction validation test set. | N11: Project Manager | O11: Fortnightly | P11: Checkpoint meeting | Q11: D-03, LR-02, LR-03, R-08 | R11: 46269 | S11: Request priority pen test slot with sponsor support | T11: 46279 | U11: =IF(OR(A11="",T11=""),"",IF(T11<Cover!$C$7,"Overdue","No")) -> No | V11: =IF(G11="Manage closely",ROW(),"") | W11: =IF(G11="Keep satisfied",ROW(),"") -> 11 | X11: =IF(G11="Keep informed",ROW(),"") | Y11: =IF(G11="Monitor",ROW(),"") | Z11: =IF(OR(J11="",N(J11)<=0),"",K11+(1000-ROW())/100000) -> 4.00989
A12: SH-08 | B12: Legal Counsel | C12: Legal | D12: Client | E12: 3 | F12: 2 | G12: =IF(A12="","",IF(AND(E12>=$E$3,F12>=$E$3),"Manage closely",IF(E12>=$E$3,"Keep satisfied",IF(F12>=$E$3,"Keep informed","Monitor")))) -> Monitor | H12: Neutral | I12: Supportive | J12: =IF(OR(A12="",H12="",I12=""),"",IF(I12="Unaware",1,IF(I12="Resistant",2,IF(I12="Neutral",3,IF(I12="Supportive",4,IF(I12="Leading",5,0)))))-IF(H12="Unaware",1,IF(H12="Resistant",2,IF(H12="Neutral",3,IF(H12="Supportive",4,IF(H12="Leading",5,0)))))) -> 1 | K12: =IF(J12="","",J12*E12) -> 3 | L12: Merchant portal terms of use, data retention obligations. | M12: Book a fixed review slot with a short pre-read highlighting only decisions needed. | N12: Product Owner | O12: Monthly | P12: Email and meeting | Q12: D-05, A-07 | R12: 46273 | S12: Confirm legal review slot for terms of use | T12: 46282 | U12: =IF(OR(A12="",T12=""),"",IF(T12<Cover!$C$7,"Overdue","No")) -> No | V12: =IF(G12="Manage closely",ROW(),"") | W12: =IF(G12="Keep satisfied",ROW(),"") | X12: =IF(G12="Keep informed",ROW(),"") | Y12: =IF(G12="Monitor",ROW(),"") -> 12 | Z12: =IF(OR(J12="",N(J12)<=0),"",K12+(1000-ROW())/100000) -> 3.00988
A13: SH-09 | B13: IAM Team Lead | C13: Identity and Access Management | D13: Client | E13: 3 | F13: 2 | G13: =IF(A13="","",IF(AND(E13>=$E$3,F13>=$E$3),"Manage closely",IF(E13>=$E$3,"Keep satisfied",IF(F13>=$E$3,"Keep informed","Monitor")))) -> Monitor | H13: Supportive | I13: Supportive | J13: =IF(OR(A13="",H13="",I13=""),"",IF(I13="Unaware",1,IF(I13="Resistant",2,IF(I13="Neutral",3,IF(I13="Supportive",4,IF(I13="Leading",5,0)))))-IF(H13="Unaware",1,IF(H13="Resistant",2,IF(H13="Neutral",3,IF(H13="Supportive",4,IF(H13="Leading",5,0)))))) -> 0 | K13: =IF(J13="","",J13*E13) -> 0 | L13: Role configuration effort and timing. | M13: Keep the Tuesday joint checkpoint; confirm acceptance criteria for role setup. | N13: Tech Lead | O13: Weekly | P13: Checkpoint meeting | Q13: D-02, A-03 | R13: 46273 | S13: Confirm role configuration on track for 30-Sep | T13: 46280 | U13: =IF(OR(A13="",T13=""),"",IF(T13<Cover!$C$7,"Overdue","No")) -> No | V13: =IF(G13="Manage closely",ROW(),"") | W13: =IF(G13="Keep satisfied",ROW(),"") | X13: =IF(G13="Keep informed",ROW(),"") | Y13: =IF(G13="Monitor",ROW(),"") -> 13 | Z13: =IF(OR(J13="",N(J13)<=0),"",K13+(1000-ROW())/100000)
A14: SH-10 | B14: Data Engineering Lead | C14: Data Engineering | D14: Client | E14: 3 | F14: 3 | G14: =IF(A14="","",IF(AND(E14>=$E$3,F14>=$E$3),"Manage closely",IF(E14>=$E$3,"Keep satisfied",IF(F14>=$E$3,"Keep informed","Monitor")))) -> Monitor | H14: Neutral | I14: Supportive | J14: =IF(OR(A14="",H14="",I14=""),"",IF(I14="Unaware",1,IF(I14="Resistant",2,IF(I14="Neutral",3,IF(I14="Supportive",4,IF(I14="Leading",5,0)))))-IF(H14="Unaware",1,IF(H14="Resistant",2,IF(H14="Neutral",3,IF(H14="Supportive",4,IF(H14="Leading",5,0)))))) -> 1 | K14: =IF(J14="","",J14*E14) -> 3 | L14: Pipeline capacity, data quality rules, ownership of settlement data issues. | M14: Agree data quality acceptance rules and exception ownership; include in sprint reviews for reporting stories. | N14: Tech Lead | O14: Fortnightly | P14: Working session | Q14: D-04, R-05, US-033 | R14: 46266 | S14: Agree pipeline acceptance rules | T14: 46286 | U14: =IF(OR(A14="",T14=""),"",IF(T14<Cover!$C$7,"Overdue","No")) -> No | V14: =IF(G14="Manage closely",ROW(),"") | W14: =IF(G14="Keep satisfied",ROW(),"") | X14: =IF(G14="Keep informed",ROW(),"") | Y14: =IF(G14="Monitor",ROW(),"") -> 14 | Z14: =IF(OR(J14="",N(J14)<=0),"",K14+(1000-ROW())/100000) -> 3.00986
A15: SH-11 | B15: Data Governance Lead | C15: Data Governance | D15: Client | E15: 4 | F15: 2 | G15: =IF(A15="","",IF(AND(E15>=$E$3,F15>=$E$3),"Manage closely",IF(E15>=$E$3,"Keep satisfied",IF(F15>=$E$3,"Keep informed","Monitor")))) -> Keep satisfied | H15: Neutral | I15: Supportive | J15: =IF(OR(A15="",H15="",I15=""),"",IF(I15="Unaware",1,IF(I15="Resistant",2,IF(I15="Neutral",3,IF(I15="Supportive",4,IF(I15="Leading",5,0)))))-IF(H15="Unaware",1,IF(H15="Resistant",2,IF(H15="Neutral",3,IF(H15="Supportive",4,IF(H15="Leading",5,0)))))) -> 1 | K15: =IF(J15="","",J15*E15) -> 4 | L15: Personal data in analytics events; approval workload. | M15: Walk through a privacy-first tracking plan with no personal or card data; ask for conditional approval to unblock pilot metrics. | N15: Product Owner | O15: Monthly | P15: Governance forum | Q15: I-06, CTL-04, KPI-08 | R15: 46273 | S15: Present revised tracking plan for approval | T15: 46296 | U15: =IF(OR(A15="",T15=""),"",IF(T15<Cover!$C$7,"Overdue","No")) -> No | V15: =IF(G15="Manage closely",ROW(),"") | W15: =IF(G15="Keep satisfied",ROW(),"") -> 15 | X15: =IF(G15="Keep informed",ROW(),"") | Y15: =IF(G15="Monitor",ROW(),"") | Z15: =IF(OR(J15="",N(J15)<=0),"",K15+(1000-ROW())/100000) -> 4.00985
A16: SH-12 | B16: Customer Servicing Lead | C16: Customer Servicing | D16: Client | E16: 3 | F16: 3 | G16: =IF(A16="","",IF(AND(E16>=$E$3,F16>=$E$3),"Manage closely",IF(E16>=$E$3,"Keep satisfied",IF(F16>=$E$3,"Keep informed","Monitor")))) -> Monitor | H16: Neutral | I16: Supportive | J16: =IF(OR(A16="",H16="",I16=""),"",IF(I16="Unaware",1,IF(I16="Resistant",2,IF(I16="Neutral",3,IF(I16="Supportive",4,IF(I16="Leading",5,0)))))-IF(H16="Unaware",1,IF(H16="Resistant",2,IF(H16="Neutral",3,IF(H16="Supportive",4,IF(H16="Leading",5,0)))))) -> 1 | K16: =IF(J16="","",J16*E16) -> 3 | L16: Agent training time, call volumes after launch, status API readiness. | M16: Include in readiness huddles from November; share servicing API demo; co-write call scripts. | N16: Product Owner | O16: Monthly | P16: Readiness huddle | Q16: D-06, LR-09, KPI-07 | R16: 46261 | S16: Invite to Sprint 8 review for status API demo | T16: 46321 | U16: =IF(OR(A16="",T16=""),"",IF(T16<Cover!$C$7,"Overdue","No")) -> No | V16: =IF(G16="Manage closely",ROW(),"") | W16: =IF(G16="Keep satisfied",ROW(),"") | X16: =IF(G16="Keep informed",ROW(),"") | Y16: =IF(G16="Monitor",ROW(),"") -> 16 | Z16: =IF(OR(J16="",N(J16)<=0),"",K16+(1000-ROW())/100000) -> 3.00984
A17: SH-13 | B17: Merchant Relationship Lead | C17: Merchant Relationships | D17: Client | E17: 4 | F17: 4 | G17: =IF(A17="","",IF(AND(E17>=$E$3,F17>=$E$3),"Manage closely",IF(E17>=$E$3,"Keep satisfied",IF(F17>=$E$3,"Keep informed","Monitor")))) -> Manage closely | H17: Supportive | I17: Leading | J17: =IF(OR(A17="",H17="",I17=""),"",IF(I17="Unaware",1,IF(I17="Resistant",2,IF(I17="Neutral",3,IF(I17="Supportive",4,IF(I17="Leading",5,0)))))-IF(H17="Unaware",1,IF(H17="Resistant",2,IF(H17="Neutral",3,IF(H17="Supportive",4,IF(H17="Leading",5,0)))))) -> 1 | K17: =IF(J17="","",J17*E17) -> 4 | L17: Merchant pushback on change, pilot recruitment, language needs. | M17: Co-own the GTM plan and pilot recruitment; give RMs an enablement pack and early demo access. | N17: Product Owner | O17: Weekly | P17: Working session | Q17: LR-10, LR-13, CR-04 | R17: 46274 | S17: Finalize pilot merchant list | T17: 46290 | U17: =IF(OR(A17="",T17=""),"",IF(T17<Cover!$C$7,"Overdue","No")) -> No | V17: =IF(G17="Manage closely",ROW(),"") -> 17 | W17: =IF(G17="Keep satisfied",ROW(),"") | X17: =IF(G17="Keep informed",ROW(),"") | Y17: =IF(G17="Monitor",ROW(),"") | Z17: =IF(OR(J17="",N(J17)<=0),"",K17+(1000-ROW())/100000) -> 4.00983
A18: SH-14 | B18: Marketing and Merchant Communications Lead | C18: Marketing | D18: Client | E18: 2 | F18: 3 | G18: =IF(A18="","",IF(AND(E18>=$E$3,F18>=$E$3),"Manage closely",IF(E18>=$E$3,"Keep satisfied",IF(F18>=$E$3,"Keep informed","Monitor")))) -> Monitor | H18: Unaware | I18: Supportive | J18: =IF(OR(A18="",H18="",I18=""),"",IF(I18="Unaware",1,IF(I18="Resistant",2,IF(I18="Neutral",3,IF(I18="Supportive",4,IF(I18="Leading",5,0)))))-IF(H18="Unaware",1,IF(H18="Resistant",2,IF(H18="Neutral",3,IF(H18="Supportive",4,IF(H18="Leading",5,0)))))) -> 3 | K18: =IF(J18="","",J18*E18) -> 6 | L18: Communication lead times, brand approval, channel choice. | M18: Brief on GTM plan and communications calendar; agree approval lead times. | N18: Merchant Relationship Lead | O18: Monthly | P18: Briefing | Q18: LR-11, LR-12 | S18: First briefing on GTM plan | T18: 46300 | U18: =IF(OR(A18="",T18=""),"",IF(T18<Cover!$C$7,"Overdue","No")) -> No | V18: =IF(G18="Manage closely",ROW(),"") | W18: =IF(G18="Keep satisfied",ROW(),"") | X18: =IF(G18="Keep informed",ROW(),"") | Y18: =IF(G18="Monitor",ROW(),"") -> 18 | Z18: =IF(OR(J18="",N(J18)<=0),"",K18+(1000-ROW())/100000) -> 6.00982
A19: SH-15 | B19: Payment Processor Account Manager | C19: Processor (vendor) | D19: Vendor | E19: 4 | F19: 3 | G19: =IF(A19="","",IF(AND(E19>=$E$3,F19>=$E$3),"Manage closely",IF(E19>=$E$3,"Keep satisfied",IF(F19>=$E$3,"Keep informed","Monitor")))) -> Keep satisfied | H19: Neutral | I19: Supportive | J19: =IF(OR(A19="",H19="",I19=""),"",IF(I19="Unaware",1,IF(I19="Resistant",2,IF(I19="Neutral",3,IF(I19="Supportive",4,IF(I19="Leading",5,0)))))-IF(H19="Unaware",1,IF(H19="Resistant",2,IF(H19="Neutral",3,IF(H19="Supportive",4,IF(H19="Leading",5,0)))))) -> 1 | K19: =IF(J19="","",J19*E19) -> 4 | L19: Sandbox stability, production access timelines, integration support effort. | M19: Weekly vendor call with tracked actions; escalate through sponsor if production access slips further. | N19: Project Manager | O19: Weekly | P19: Vendor call | Q19: D-01, I-01, A-02 | R19: 46273 | S19: Escalate sandbox status defect and production access date | T19: 46280 | U19: =IF(OR(A19="",T19=""),"",IF(T19<Cover!$C$7,"Overdue","No")) -> No | V19: =IF(G19="Manage closely",ROW(),"") | W19: =IF(G19="Keep satisfied",ROW(),"") -> 19 | X19: =IF(G19="Keep informed",ROW(),"") | Y19: =IF(G19="Monitor",ROW(),"") | Z19: =IF(OR(J19="",N(J19)<=0),"",K19+(1000-ROW())/100000) -> 4.00981
A20: SH-16 | B20: Document Storage Vendor | C20: Storage vendor | D20: Vendor | E20: 2 | F20: 2 | G20: =IF(A20="","",IF(AND(E20>=$E$3,F20>=$E$3),"Manage closely",IF(E20>=$E$3,"Keep satisfied",IF(F20>=$E$3,"Keep informed","Monitor")))) -> Monitor | H20: Neutral | I20: Neutral | J20: =IF(OR(A20="",H20="",I20=""),"",IF(I20="Unaware",1,IF(I20="Resistant",2,IF(I20="Neutral",3,IF(I20="Supportive",4,IF(I20="Leading",5,0)))))-IF(H20="Unaware",1,IF(H20="Resistant",2,IF(H20="Neutral",3,IF(H20="Supportive",4,IF(H20="Leading",5,0)))))) -> 0 | K20: =IF(J20="","",J20*E20) -> 0 | L20: Completing the third-party risk assessment. | M20: Send questionnaire and SOC 2 request early; monitor only. | N20: Tech Lead | O20: As needed | P20: Email | Q20: R-08 | R20: 46268 | S20: Chase security questionnaire | T20: 46274 | U20: =IF(OR(A20="",T20=""),"",IF(T20<Cover!$C$7,"Overdue","No")) -> Overdue | V20: =IF(G20="Manage closely",ROW(),"") | W20: =IF(G20="Keep satisfied",ROW(),"") | X20: =IF(G20="Keep informed",ROW(),"") | Y20: =IF(G20="Monitor",ROW(),"") -> 20 | Z20: =IF(OR(J20="",N(J20)<=0),"",K20+(1000-ROW())/100000)
A21: SH-17 | B21: Pilot merchants (10) | C21: Merchants | D21: External | E21: 2 | F21: 5 | G21: =IF(A21="","",IF(AND(E21>=$E$3,F21>=$E$3),"Manage closely",IF(E21>=$E$3,"Keep satisfied",IF(F21>=$E$3,"Keep informed","Monitor")))) -> Keep informed | H21: Unaware | I21: Supportive | J21: =IF(OR(A21="",H21="",I21=""),"",IF(I21="Unaware",1,IF(I21="Resistant",2,IF(I21="Neutral",3,IF(I21="Supportive",4,IF(I21="Leading",5,0)))))-IF(H21="Unaware",1,IF(H21="Resistant",2,IF(H21="Neutral",3,IF(H21="Supportive",4,IF(H21="Leading",5,0)))))) -> 3 | K21: =IF(J21="","",J21*E21) -> 6 | L21: Ease of use, time saved, confidence their deadlines are safe. | M21: White-glove onboarding, weekly feedback calls during pilot, visible changes made from their feedback. | N21: Merchant Relationship Lead | O21: Weekly during pilot | P21: Onboarding and feedback calls | Q21: A-01, R-04, KPI-08 | S21: Send pilot invitations once terms are approved | T21: 46328 | U21: =IF(OR(A21="",T21=""),"",IF(T21<Cover!$C$7,"Overdue","No")) -> No | V21: =IF(G21="Manage closely",ROW(),"") | W21: =IF(G21="Keep satisfied",ROW(),"") | X21: =IF(G21="Keep informed",ROW(),"") -> 21 | Y21: =IF(G21="Monitor",ROW(),"") | Z21: =IF(OR(J21="",N(J21)<=0),"",K21+(1000-ROW())/100000) -> 6.00979
A22: SH-18 | B22: Delivery squads (Portal, Integration, Data) | C22: Delivery team | D22: Delivery partner | E22: 3 | F22: 5 | G22: =IF(A22="","",IF(AND(E22>=$E$3,F22>=$E$3),"Manage closely",IF(E22>=$E$3,"Keep satisfied",IF(F22>=$E$3,"Keep informed","Monitor")))) -> Keep informed | H22: Supportive | I22: Supportive | J22: =IF(OR(A22="",H22="",I22=""),"",IF(I22="Unaware",1,IF(I22="Resistant",2,IF(I22="Neutral",3,IF(I22="Supportive",4,IF(I22="Leading",5,0)))))-IF(H22="Unaware",1,IF(H22="Resistant",2,IF(H22="Neutral",3,IF(H22="Supportive",4,IF(H22="Leading",5,0)))))) -> 0 | K22: =IF(J22="","",J22*E22) -> 0 | L22: Clear priorities, fast unblocking, stable scope. | M22: Sprint ceremonies; blockers raised daily and tracked in RAID; explain every scope change and why. | N22: Product Owner | O22: Daily | P22: Stand-up and sprint ceremonies | Q22: I-01, R-07 | R22: 46275 | S22: Sprint 4 review and retrospective | T22: 46276 | U22: =IF(OR(A22="",T22=""),"",IF(T22<Cover!$C$7,"Overdue","No")) -> No | V22: =IF(G22="Manage closely",ROW(),"") | W22: =IF(G22="Keep satisfied",ROW(),"") | X22: =IF(G22="Keep informed",ROW(),"") -> 22 | Y22: =IF(G22="Monitor",ROW(),"") | Z22: =IF(OR(J22="",N(J22)<=0),"",K22+(1000-ROW())/100000)
G23: =IF(A23="","",IF(AND(E23>=$E$3,F23>=$E$3),"Manage closely",IF(E23>=$E$3,"Keep satisfied",IF(F23>=$E$3,"Keep informed","Monitor")))) | J23: =IF(OR(A23="",H23="",I23=""),"",IF(I23="Unaware",1,IF(I23="Resistant",2,IF(I23="Neutral",3,IF(I23="Supportive",4,IF(I23="Leading",5,0)))))-IF(H23="Unaware",1,IF(H23="Resistant",2,IF(H23="Neutral",3,IF(H23="Supportive",4,IF(H23="Leading",5,0)))))) | K23: =IF(J23="","",J23*E23) | U23: =IF(OR(A23="",T23=""),"",IF(T23<Cover!$C$7,"Overdue","No")) | V23: =IF(G23="Manage closely",ROW(),"") | W23: =IF(G23="Keep satisfied",ROW(),"") | X23: =IF(G23="Keep informed",ROW(),"") | Y23: =IF(G23="Monitor",ROW(),"") | Z23: =IF(OR(J23="",N(J23)<=0),"",K23+(1000-ROW())/100000)
G24: =IF(A24="","",IF(AND(E24>=$E$3,F24>=$E$3),"Manage closely",IF(E24>=$E$3,"Keep satisfied",IF(F24>=$E$3,"Keep informed","Monitor")))) | J24: =IF(OR(A24="",H24="",I24=""),"",IF(I24="Unaware",1,IF(I24="Resistant",2,IF(I24="Neutral",3,IF(I24="Supportive",4,IF(I24="Leading",5,0)))))-IF(H24="Unaware",1,IF(H24="Resistant",2,IF(H24="Neutral",3,IF(H24="Supportive",4,IF(H24="Leading",5,0)))))) | K24: =IF(J24="","",J24*E24) | U24: =IF(OR(A24="",T24=""),"",IF(T24<Cover!$C$7,"Overdue","No")) | V24: =IF(G24="Manage closely",ROW(),"") | W24: =IF(G24="Keep satisfied",ROW(),"") | X24: =IF(G24="Keep informed",ROW(),"") | Y24: =IF(G24="Monitor",ROW(),"") | Z24: =IF(OR(J24="",N(J24)<=0),"",K24+(1000-ROW())/100000)
G25: =IF(A25="","",IF(AND(E25>=$E$3,F25>=$E$3),"Manage closely",IF(E25>=$E$3,"Keep satisfied",IF(F25>=$E$3,"Keep informed","Monitor")))) | J25: =IF(OR(A25="",H25="",I25=""),"",IF(I25="Unaware",1,IF(I25="Resistant",2,IF(I25="Neutral",3,IF(I25="Supportive",4,IF(I25="Leading",5,0)))))-IF(H25="Unaware",1,IF(H25="Resistant",2,IF(H25="Neutral",3,IF(H25="Supportive",4,IF(H25="Leading",5,0)))))) | K25: =IF(J25="","",J25*E25) | U25: =IF(OR(A25="",T25=""),"",IF(T25<Cover!$C$7,"Overdue","No")) | V25: =IF(G25="Manage closely",ROW(),"") | W25: =IF(G25="Keep satisfied",ROW(),"") | X25: =IF(G25="Keep informed",ROW(),"") | Y25: =IF(G25="Monitor",ROW(),"") | Z25: =IF(OR(J25="",N(J25)<=0),"",K25+(1000-ROW())/100000)
G26: =IF(A26="","",IF(AND(E26>=$E$3,F26>=$E$3),"Manage closely",IF(E26>=$E$3,"Keep satisfied",IF(F26>=$E$3,"Keep informed","Monitor")))) | J26: =IF(OR(A26="",H26="",I26=""),"",IF(I26="Unaware",1,IF(I26="Resistant",2,IF(I26="Neutral",3,IF(I26="Supportive",4,IF(I26="Leading",5,0)))))-IF(H26="Unaware",1,IF(H26="Resistant",2,IF(H26="Neutral",3,IF(H26="Supportive",4,IF(H26="Leading",5,0)))))) | K26: =IF(J26="","",J26*E26) | U26: =IF(OR(A26="",T26=""),"",IF(T26<Cover!$C$7,"Overdue","No")) | V26: =IF(G26="Manage closely",ROW(),"") | W26: =IF(G26="Keep satisfied",ROW(),"") | X26: =IF(G26="Keep informed",ROW(),"") | Y26: =IF(G26="Monitor",ROW(),"") | Z26: =IF(OR(J26="",N(J26)<=0),"",K26+(1000-ROW())/100000)
G27: =IF(A27="","",IF(AND(E27>=$E$3,F27>=$E$3),"Manage closely",IF(E27>=$E$3,"Keep satisfied",IF(F27>=$E$3,"Keep informed","Monitor")))) | J27: =IF(OR(A27="",H27="",I27=""),"",IF(I27="Unaware",1,IF(I27="Resistant",2,IF(I27="Neutral",3,IF(I27="Supportive",4,IF(I27="Leading",5,0)))))-IF(H27="Unaware",1,IF(H27="Resistant",2,IF(H27="Neutral",3,IF(H27="Supportive",4,IF(H27="Leading",5,0)))))) | K27: =IF(J27="","",J27*E27) | U27: =IF(OR(A27="",T27=""),"",IF(T27<Cover!$C$7,"Overdue","No")) | V27: =IF(G27="Manage closely",ROW(),"") | W27: =IF(G27="Keep satisfied",ROW(),"") | X27: =IF(G27="Keep informed",ROW(),"") | Y27: =IF(G27="Monitor",ROW(),"") | Z27: =IF(OR(J27="",N(J27)<=0),"",K27+(1000-ROW())/100000)
G28: =IF(A28="","",IF(AND(E28>=$E$3,F28>=$E$3),"Manage closely",IF(E28>=$E$3,"Keep satisfied",IF(F28>=$E$3,"Keep informed","Monitor")))) | J28: =IF(OR(A28="",H28="",I28=""),"",IF(I28="Unaware",1,IF(I28="Resistant",2,IF(I28="Neutral",3,IF(I28="Supportive",4,IF(I28="Leading",5,0)))))-IF(H28="Unaware",1,IF(H28="Resistant",2,IF(H28="Neutral",3,IF(H28="Supportive",4,IF(H28="Leading",5,0)))))) | K28: =IF(J28="","",J28*E28) | U28: =IF(OR(A28="",T28=""),"",IF(T28<Cover!$C$7,"Overdue","No")) | V28: =IF(G28="Manage closely",ROW(),"") | W28: =IF(G28="Keep satisfied",ROW(),"") | X28: =IF(G28="Keep informed",ROW(),"") | Y28: =IF(G28="Monitor",ROW(),"") | Z28: =IF(OR(J28="",N(J28)<=0),"",K28+(1000-ROW())/100000)
G29: =IF(A29="","",IF(AND(E29>=$E$3,F29>=$E$3),"Manage closely",IF(E29>=$E$3,"Keep satisfied",IF(F29>=$E$3,"Keep informed","Monitor")))) | J29: =IF(OR(A29="",H29="",I29=""),"",IF(I29="Unaware",1,IF(I29="Resistant",2,IF(I29="Neutral",3,IF(I29="Supportive",4,IF(I29="Leading",5,0)))))-IF(H29="Unaware",1,IF(H29="Resistant",2,IF(H29="Neutral",3,IF(H29="Supportive",4,IF(H29="Leading",5,0)))))) | K29: =IF(J29="","",J29*E29) | U29: =IF(OR(A29="",T29=""),"",IF(T29<Cover!$C$7,"Overdue","No")) | V29: =IF(G29="Manage closely",ROW(),"") | W29: =IF(G29="Keep satisfied",ROW(),"") | X29: =IF(G29="Keep informed",ROW(),"") | Y29: =IF(G29="Monitor",ROW(),"") | Z29: =IF(OR(J29="",N(J29)<=0),"",K29+(1000-ROW())/100000)
G30: =IF(A30="","",IF(AND(E30>=$E$3,F30>=$E$3),"Manage closely",IF(E30>=$E$3,"Keep satisfied",IF(F30>=$E$3,"Keep informed","Monitor")))) | J30: =IF(OR(A30="",H30="",I30=""),"",IF(I30="Unaware",1,IF(I30="Resistant",2,IF(I30="Neutral",3,IF(I30="Supportive",4,IF(I30="Leading",5,0)))))-IF(H30="Unaware",1,IF(H30="Resistant",2,IF(H30="Neutral",3,IF(H30="Supportive",4,IF(H30="Leading",5,0)))))) | K30: =IF(J30="","",J30*E30) | U30: =IF(OR(A30="",T30=""),"",IF(T30<Cover!$C$7,"Overdue","No")) | V30: =IF(G30="Manage closely",ROW(),"") | W30: =IF(G30="Keep satisfied",ROW(),"") | X30: =IF(G30="Keep informed",ROW(),"") | Y30: =IF(G30="Monitor",ROW(),"") | Z30: =IF(OR(J30="",N(J30)<=0),"",K30+(1000-ROW())/100000)
G31: =IF(A31="","",IF(AND(E31>=$E$3,F31>=$E$3),"Manage closely",IF(E31>=$E$3,"Keep satisfied",IF(F31>=$E$3,"Keep informed","Monitor")))) | J31: =IF(OR(A31="",H31="",I31=""),"",IF(I31="Unaware",1,IF(I31="Resistant",2,IF(I31="Neutral",3,IF(I31="Supportive",4,IF(I31="Leading",5,0)))))-IF(H31="Unaware",1,IF(H31="Resistant",2,IF(H31="Neutral",3,IF(H31="Supportive",4,IF(H31="Leading",5,0)))))) | K31: =IF(J31="","",J31*E31) | U31: =IF(OR(A31="",T31=""),"",IF(T31<Cover!$C$7,"Overdue","No")) | V31: =IF(G31="Manage closely",ROW(),"") | W31: =IF(G31="Keep satisfied",ROW(),"") | X31: =IF(G31="Keep informed",ROW(),"") | Y31: =IF(G31="Monitor",ROW(),"") | Z31: =IF(OR(J31="",N(J31)<=0),"",K31+(1000-ROW())/100000)
G32: =IF(A32="","",IF(AND(E32>=$E$3,F32>=$E$3),"Manage closely",IF(E32>=$E$3,"Keep satisfied",IF(F32>=$E$3,"Keep informed","Monitor")))) | J32: =IF(OR(A32="",H32="",I32=""),"",IF(I32="Unaware",1,IF(I32="Resistant",2,IF(I32="Neutral",3,IF(I32="Supportive",4,IF(I32="Leading",5,0)))))-IF(H32="Unaware",1,IF(H32="Resistant",2,IF(H32="Neutral",3,IF(H32="Supportive",4,IF(H32="Leading",5,0)))))) | K32: =IF(J32="","",J32*E32) | U32: =IF(OR(A32="",T32=""),"",IF(T32<Cover!$C$7,"Overdue","No")) | V32: =IF(G32="Manage closely",ROW(),"") | W32: =IF(G32="Keep satisfied",ROW(),"") | X32: =IF(G32="Keep informed",ROW(),"") | Y32: =IF(G32="Monitor",ROW(),"") | Z32: =IF(OR(J32="",N(J32)<=0),"",K32+(1000-ROW())/100000)
G33: =IF(A33="","",IF(AND(E33>=$E$3,F33>=$E$3),"Manage closely",IF(E33>=$E$3,"Keep satisfied",IF(F33>=$E$3,"Keep informed","Monitor")))) | J33: =IF(OR(A33="",H33="",I33=""),"",IF(I33="Unaware",1,IF(I33="Resistant",2,IF(I33="Neutral",3,IF(I33="Supportive",4,IF(I33="Leading",5,0)))))-IF(H33="Unaware",1,IF(H33="Resistant",2,IF(H33="Neutral",3,IF(H33="Supportive",4,IF(H33="Leading",5,0)))))) | K33: =IF(J33="","",J33*E33) | U33: =IF(OR(A33="",T33=""),"",IF(T33<Cover!$C$7,"Overdue","No")) | V33: =IF(G33="Manage closely",ROW(),"") | W33: =IF(G33="Keep satisfied",ROW(),"") | X33: =IF(G33="Keep informed",ROW(),"") | Y33: =IF(G33="Monitor",ROW(),"") | Z33: =IF(OR(J33="",N(J33)<=0),"",K33+(1000-ROW())/100000)
G34: =IF(A34="","",IF(AND(E34>=$E$3,F34>=$E$3),"Manage closely",IF(E34>=$E$3,"Keep satisfied",IF(F34>=$E$3,"Keep informed","Monitor")))) | J34: =IF(OR(A34="",H34="",I34=""),"",IF(I34="Unaware",1,IF(I34="Resistant",2,IF(I34="Neutral",3,IF(I34="Supportive",4,IF(I34="Leading",5,0)))))-IF(H34="Unaware",1,IF(H34="Resistant",2,IF(H34="Neutral",3,IF(H34="Supportive",4,IF(H34="Leading",5,0)))))) | K34: =IF(J34="","",J34*E34) | U34: =IF(OR(A34="",T34=""),"",IF(T34<Cover!$C$7,"Overdue","No")) | V34: =IF(G34="Manage closely",ROW(),"") | W34: =IF(G34="Keep satisfied",ROW(),"") | X34: =IF(G34="Keep informed",ROW(),"") | Y34: =IF(G34="Monitor",ROW(),"") | Z34: =IF(OR(J34="",N(J34)<=0),"",K34+(1000-ROW())/100000)
... G54: =IF(A54="","",IF(AND(E54>=$E$3,F54>=$E$3),"Manage closely",IF(E54>=$E$3,"Keep satisfied",IF(F54>=$E$3,"Keep informed","Monitor")))) | J54: =IF(OR(A54="",H54="",I54=""),"",IF(I54="Unaware",1,IF(I54="Resistant",2,IF(I54="Neutral",3,IF(I54="Supportive",4,IF(I54="Leading",5,0)))))-IF(H54="Unaware",1,IF(H54="Resistant",2,IF(H54="Neutral",3,IF(H54="Supportive",4,IF(H54="Leading",5,0)))))) | K54: =IF(J54="","",J54*E54) | U54: =IF(OR(A54="",T54=""),"",IF(T54<Cover!$C$7,"Overdue","No")) | V54: =IF(G54="Manage closely",ROW(),"") | W54: =IF(G54="Keep satisfied",ROW(),"") | X54: =IF(G54="Keep informed",ROW(),"") | Y54: =IF(G54="Monitor",ROW(),"") | Z54: =IF(OR(J54="",N(J54)<=0),"",K54+(1000-ROW())/100000)

Sheet RACI Matrix
A1: RACI Matrix
A2: Merchant Payment Operations & Dispute Hub · Simulation project · Decision rights align with Change Log thresholds
A3: Use R, A, C, I or R/A. Each activity needs exactly one A and at least one R; the Check column flags problems.
A4: ID | B4: Activity or decision | C4: Area | D4: Business Sponsor | E4: Steering Committee | F4: Engagement Lead | G4: Product Owner | H4: Project Manager | I4: Tech Lead | J4: Dispute Ops Lead | K4: Finance Lead | L4: Compliance Lead | M4: InfoSec Lead | N4: Legal Counsel | O4: Data Governance Lead | P4: Merchant Relationship Lead | Q4: Servicing Lead | R4: A count | S4: R count | T4: Check
A5: RA-01 | B5: Approve MVP scope baseline | C5: Scope | D5: A | E5: I | F5: C | G5: R | H5: C | I5: C | J5: C | K5: C | L5: C | P5: C | R5: =IF(A5="","",COUNTIF(D5:Q5,"*A*")) -> 1 | S5: =IF(A5="","",COUNTIF(D5:Q5,"*R*")) -> 1 | T5: =IF(A5="","",IF(R5<>1,"Needs one A",IF(S5<1,"Needs an R","OK"))) -> OK
A6: RA-02 | B6: Prioritize and order the product backlog | C6: Scope | D6: C | G6: R/A | H6: I | I6: C | J6: C | R6: =IF(A6="","",COUNTIF(D6:Q6,"*A*")) -> 1 | S6: =IF(A6="","",COUNTIF(D6:Q6,"*R*")) -> 1 | T6: =IF(A6="","",IF(R6<>1,"Needs one A",IF(S6<1,"Needs an R","OK"))) -> OK
A7: RA-03 | B7: Approve Low-impact change requests | C7: Change control | D7: I | G7: R/A | H7: I | I7: C | R7: =IF(A7="","",COUNTIF(D7:Q7,"*A*")) -> 1 | S7: =IF(A7="","",COUNTIF(D7:Q7,"*R*")) -> 1 | T7: =IF(A7="","",IF(R7<>1,"Needs one A",IF(S7<1,"Needs an R","OK"))) -> OK
A8: RA-04 | B8: Approve Medium-impact change requests | C8: Change control | D8: A | E8: I | G8: R | H8: C | I8: C | K8: C | R8: =IF(A8="","",COUNTIF(D8:Q8,"*A*")) -> 1 | S8: =IF(A8="","",COUNTIF(D8:Q8,"*R*")) -> 1 | T8: =IF(A8="","",IF(R8<>1,"Needs one A",IF(S8<1,"Needs an R","OK"))) -> OK
A9: RA-05 | B9: Approve High-impact and compliance change requests | C9: Change control | D9: C | E9: A | F9: C | G9: R | H9: C | I9: C | K9: C | L9: C | R9: =IF(A9="","",COUNTIF(D9:Q9,"*A*")) -> 1 | S9: =IF(A9="","",COUNTIF(D9:Q9,"*R*")) -> 1 | T9: =IF(A9="","",IF(R9<>1,"Needs one A",IF(S9<1,"Needs an R","OK"))) -> OK
A10: RA-06 | B10: Maintain RAID log and escalate risks | C10: Governance | D10: I | E10: I | F10: C | G10: R | H10: A | I10: R | R10: =IF(A10="","",COUNTIF(D10:Q10,"*A*")) -> 1 | S10: =IF(A10="","",COUNTIF(D10:Q10,"*R*")) -> 2 | T10: =IF(A10="","",IF(R10<>1,"Needs one A",IF(S10<1,"Needs an R","OK"))) -> OK
A11: RA-07 | B11: Approve compliance controls and evidence | C11: Compliance | G11: R | I11: R | L11: A | M11: C | N11: C | O11: C | R11: =IF(A11="","",COUNTIF(D11:Q11,"*A*")) -> 1 | S11: =IF(A11="","",COUNTIF(D11:Q11,"*R*")) -> 2 | T11: =IF(A11="","",IF(R11<>1,"Needs one A",IF(S11<1,"Needs an R","OK"))) -> OK
A12: RA-08 | B12: Security sign-off for go-live | C12: Compliance | E12: I | G12: I | H12: I | I12: R | L12: C | M12: A | R12: =IF(A12="","",COUNTIF(D12:Q12,"*A*")) -> 1 | S12: =IF(A12="","",COUNTIF(D12:Q12,"*R*")) -> 1 | T12: =IF(A12="","",IF(R12<>1,"Needs one A",IF(S12<1,"Needs an R","OK"))) -> OK
A13: RA-09 | B13: Approve analytics tracking plan | C13: Data | G13: R | I13: C | L13: C | O13: A | R13: =IF(A13="","",COUNTIF(D13:Q13,"*A*")) -> 1 | S13: =IF(A13="","",COUNTIF(D13:Q13,"*R*")) -> 1 | T13: =IF(A13="","",IF(R13<>1,"Needs one A",IF(S13<1,"Needs an R","OK"))) -> OK
A14: RA-10 | B14: Approve KPI and dispute outcome definitions | C14: Data | D14: A | E14: I | G14: R | J14: C | K14: C | O14: C | R14: =IF(A14="","",COUNTIF(D14:Q14,"*A*")) -> 1 | S14: =IF(A14="","",COUNTIF(D14:Q14,"*R*")) -> 1 | T14: =IF(A14="","",IF(R14<>1,"Needs one A",IF(S14<1,"Needs an R","OK"))) -> OK
A15: RA-11 | B15: Execute user acceptance testing | C15: Quality | G15: A | H15: C | I15: C | J15: R | K15: R | Q15: C | R15: =IF(A15="","",COUNTIF(D15:Q15,"*A*")) -> 1 | S15: =IF(A15="","",COUNTIF(D15:Q15,"*R*")) -> 2 | T15: =IF(A15="","",IF(R15<>1,"Needs one A",IF(S15<1,"Needs an R","OK"))) -> OK
